Workbook
Name Limite_descuento: #REF!

Sheet Ventas
A1: Referencia de la orden | B1: Fecha de la orden | C1: Cliente | D1: Vendedor | E1: Términos de pago | F1: Lista de precios/ID | G1: Lista de precios/Nombre de la lista de precios | H1: Líneas de la orden/Producto/Categoría del producto | I1: Líneas de la orden/Producto/Referencia interna | J1: Líneas de la orden/Producto/Nombre en pantalla | K1: Líneas de la orden/Precio unitario | L1: Líneas de la orden/Subtotal | M1: Líneas de la orden/Cantidad | N1: Líneas de la orden/Descuento (%) | O1: Subtotal Orden | P1: Total Orden | Q1: Factura Nro | R1: Factura Fecha | S1: Factura Producto | T1: Factura Precio Unitario $ | U1: Factura Cantidad | V1: Factura Descuento % | W1: Factura Total $ | X1: Pago Nro | Y1: Pago ID | Z1: Pago Fecha | AA1: Pago Moneda | AB1: Pago Importe Firmado | AC1: Pago Método / Diario | AD1: Descuento Diferencial % | AE1: Descuento Pronto Pago % | AF1: Otros Descuentos % | AG1: Descuento Total Aplicado % | AH1: Total Orden con Descuentos | AI1: Total Factura con Descuentos | AJ1: Monto Pagado Total USD | AK1: Saldo Deudor sobre Orden | AL1: Saldo Deudor sobre Factura | AM1: Diferencia de Totales Orden vs Factura | AN1: ID Número de Orden | AO1: Validación Diferencial | AP1: Validación Pronto Pago | AQ1: Validación Descuento Previo | AR1: Validación General
A2: =IF('Ordenes_Odoo'!A2="","",'Ordenes_Odoo'!A2) | B2: =IF('Ordenes_Odoo'!B2="","",'Ordenes_Odoo'!B2) | C2: =IF('Ordenes_Odoo'!C2="","",'Ordenes_Odoo'!C2) | D2: =IF('Ordenes_Odoo'!D2="","",'Ordenes_Odoo'!D2) | E2: =IF('Ordenes_Odoo'!E2="","",'Ordenes_Odoo'!E2) | F2: =IF('Ordenes_Odoo'!F2="","",'Ordenes_Odoo'!F2) | G2: =IF('Ordenes_Odoo'!G2="","",'Ordenes_Odoo'!G2) | H2: =IF('Ordenes_Odoo'!H2="","",'Ordenes_Odoo'!H2) | ... P2: =IF('Ordenes_Odoo'!P2="","",'Ordenes_Odoo'!P2) | Q2: =IF(A2="","",IFERROR(INDEX(Facturas_Odoo!$B:$B, MATCH(A2, Facturas_Odoo!$D:$D, 0)), "Sin Factura")) | R2: =IF(Q2="Sin Factura","",IFERROR(INDEX(Facturas_Odoo!$A:$A, MATCH(Q2, Facturas_Odoo!$B:$B, 0)), "")) | S2: =IF(Q2="Sin Factura","",IFERROR(_xlfn.XLOOKUP(1, (Facturas_Odoo!$D:$D=A2) * (Facturas_Odoo!$K:$K=I2), Facturas_Odoo!$L:$L, ""), "")) | T2: =IF(Q2="Sin Factura",0,IFERROR(_xlfn.XLOOKUP(1, (Facturas_Odoo!$D:$D=A2) * (Facturas_Odoo!$K:$K=I2), Facturas_Odoo!$M:$M, 0), 0)) | U2: =IF(Q2="Sin Factura",0,IFERROR(_xlfn.XLOOKUP(1, (Facturas_Odoo!$D:$D=A2) * (Facturas_Odoo!$K:$K=I2), Facturas_Odoo!$N:$N, 0), 0)) | V2: =IF(Q2="Sin Factura",0,IFERROR(_xlfn.XLOOKUP(1, (Facturas_Odoo!$D:$D=A2) * (Facturas_Odoo!$K:$K=I2), Facturas_Odoo!$O:$O, 0), 0)) | W2: =IF(Q2="Sin Factura",0,IFERROR(_xlfn.XLOOKUP(1, (Facturas_Odoo!$D:$D=A2) * (Facturas_Odoo!$K:$K=I2), Facturas_Odoo!$Q:$Q, 0), 0)) | X2: =IF(OR(Q2="Sin Factura",Q2=""),"",IFERROR(INDEX(Pagos_Odoo!$B:$B, MATCH(Q2, Pagos_Odoo!$I:$I, 0)), "Sin Pago")) | Y2: =IF(X2="Sin Pago","",IFERROR(INDEX(Pagos_Odoo!$C:$C, MATCH(X2, Pagos_Odoo!$B:$B, 0)), "")) | Z2: =IF(X2="Sin Pago","",IFERROR(INDEX(Pagos_Odoo!$A:$A, MATCH(X2, Pagos_Odoo!$B:$B, 0)), "")) | AA2: =IF(X2="Sin Pago","",IFERROR(INDEX(Pagos_Odoo!$F:$F, MATCH(X2, Pagos_Odoo!$B:$B, 0)), "")) | AB2: =IF(X2="Sin Pago",0,IFERROR(INDEX(Pagos_Odoo!$E:$E, MATCH(X2, Pagos_Odoo!$B:$B, 0)), 0)) | AC2: =IF(X2="Sin Pago","",IFERROR(INDEX(Pagos_Odoo!$G:$G, MATCH(X2, Pagos_Odoo!$B:$B, 0)), "")) | AD2: 0 | AG2: =IF(AN2="","",AD2+AE2+AF2) | AH2: =IF(AN2="","",P2*(1-AG2)) | AI2: =IF(AN2="","",IF(Q2="Sin Factura",0,IFERROR(INDEX(Facturas_Odoo!$H:$H, MATCH(Q2, Facturas_Odoo!$B:$B, 0)), 0)*(1-AG2))) | AJ2: =IF(AN2="","",_xlfn.LET(idVenta, AN2&"", pagos, IFERROR(SUMIF(Aux_Datos!$B:$B, idVenta, Aux_Datos!$L:$L), 0), retenciones, IFERROR(SUMIF(Aux_Datos!$O:$O, idVenta, Aux_Datos!$S:$S), 0), pagos_manuales, IFERROR(SUMIF('Asignación Pagos'!$G:$G, idVenta, 'Asignación Pagos'!$F:$F), 0), pagos+retenciones+pagos_manuales)) | AK2: =IF(AN2="","",AH2-AJ2) | AL2: =IF(AN2="","",IF(Q2="Sin Factura","",AI2-AJ2)) | AM2: =IF(AN2="","",IF(Q2="Sin Factura",0,P2-IFERROR(INDEX(Facturas_Odoo!$H:$H, MATCH(Q2, Facturas_Odoo!$B:$B, 0)), 0))) | AN2: =VALUE(MID(A2,2,LEN(A2))) | AO2: =IF(AN2="","",IF(AD2=0,"OK",_xlfn.LET(monedaPago, IF(AA2="","USD",AA2), limitePermitido, IFERROR(VLOOKUP(monedaPago, Configuración!$A$2:$B$3, 2, FALSE), 0.15), IF(AD2>limitePermitido, "ALERTA: EXCESO (" & TEXT(limitePermitido, "0%") & " máx)", "OK")))) | AP2: =IF(AN2="","",IF(AE2=0,"OK",_xlfn.LET(fechaPago, Z2, fechaFactura, R2, diasCredito, IF(E2="Pago inmediato", 0, IFERROR(VALUE(MID(E2, 1, SEARCH(" ", E2)-1)), 0)), tolerancia, Configuración!$E$2, limiteDias, diasCredito + tolerancia, IF(OR(fechaPago="", fechaFactura=""), "REVISAR: SIN FECHA", IF(fechaPago - fechaFactura > limiteDias, "ALERTA: PAGO FUERA DE PLAZO (" & (fechaPago - fechaFactura) & " días)", "OK"))))) | AQ2: =IF(AN2="","",IF(AND(N2>0, AG2>0), IF(Configuración!$K$2="NO", "ALERTA: DESCUENTO DOBLE NO PERMITIDO", "OK"), "OK")) | AR2: =IF(AN2="","",IF(OR(AO2<>"OK", AP2<>"OK", AQ2<>"OK"), "⚠️ REVISAR", "OK"))
A3: =IF('Ordenes_Odoo'!A3="","",'Ordenes_Odoo'!A3) | B3: =IF('Ordenes_Odoo'!B3="","",'Ordenes_Odoo'!B3) | C3: =IF('Ordenes_Odoo'!C3="","",'Ordenes_Odoo'!C3) | D3: =IF('Ordenes_Odoo'!D3="","",'Ordenes_Odoo'!D3) | E3: =IF('Ordenes_Odoo'!E3="","",'Ordenes_Odoo'!E3) | F3: =IF('Ordenes_Odoo'!F3="","",'Ordenes_Odoo'!F3) | G3: =IF('Ordenes_Odoo'!G3="","",'Ordenes_Odoo'!G3) | H3: =IF('Ordenes_Odoo'!H3="","",'Ordenes_Odoo'!H3) | ... P3: =IF('Ordenes_Odoo'!P3="","",'Ordenes_Odoo'!P3) | Q3: =IF(A3="","",IFERROR(INDEX(Facturas_Odoo!$B:$B, MATCH(A3, Facturas_Odoo!$D:$D, 0)), "Sin Factura")) | R3: =IF(Q3="Sin Factura","",IFERROR(INDEX(Facturas_Odoo!$A:$A, MATCH(Q3, Facturas_Odoo!$B:$B, 0)), "")) | S3: =IF(Q3="Sin Factura","",IFERROR(_xlfn.XLOOKUP(1, (Facturas_Odoo!$D:$D=A3) * (Facturas_Odoo!$K:$K=I3), Facturas_Odoo!$L:$L, ""), "")) | T3: =IF(Q3="Sin Factura",0,IFERROR(_xlfn.XLOOKUP(1, (Facturas_Odoo!$D:$D=A3) * (Facturas_Odoo!$K:$K=I3), Facturas_Odoo!$M:$M, 0), 0)) | U3: =IF(Q3="Sin Factura",0,IFERROR(_xlfn.XLOOKUP(1, (Facturas_Odoo!$D:$D=A3) * (Facturas_Odoo!$K:$K=I3), Facturas_Odoo!$N:$N, 0), 0)) | V3: =IF(Q3="Sin Factura",0,IFERROR(_xlfn.XLOOKUP(1, (Facturas_Odoo!$D:$D=A3) * (Facturas_Odoo!$K:$K=I3), Facturas_Odoo!$O:$O, 0), 0)) | W3: =IF(Q3="Sin Factura",0,IFERROR(_xlfn.XLOOKUP(1, (Facturas_Odoo!$D:$D=A3) * (Facturas_Odoo!$K:$K=I3), Facturas_Odoo!$Q:$Q, 0), 0)) | X3: =IF(OR(Q3="Sin Factura",Q3=""),"",IFERROR(INDEX(Pagos_Odoo!$B:$B, MATCH(Q3, Pagos_Odoo!$I:$I, 0)), "Sin Pago")) | Y3: =IF(X3="Sin Pago","",IFERROR(INDEX(Pagos_Odoo!$C:$C, MATCH(X3, Pagos_Odoo!$B:$B, 0)), "")) | Z3: =IF(X3="Sin Pago","",IFERROR(INDEX(Pagos_Odoo!$A:$A, MATCH(X3, Pagos_Odoo!$B:$B, 0)), "")) | AA3: =IF(X3="Sin Pago","",IFERROR(INDEX(Pagos_Odoo!$F:$F, MATCH(X3, Pagos_Odoo!$B:$B, 0)), "")) | AB3: =IF(X3="Sin Pago",0,IFERROR(INDEX(Pagos_Odoo!$E:$E, MATCH(X3, Pagos_Odoo!$B:$B, 0)), 0)) | AC3: =IF(X3="Sin Pago","",IFERROR(INDEX(Pagos_Odoo!$G:$G, MATCH(X3, Pagos_Odoo!$B:$B, 0)), "")) | AD3: 0 | AG3: =IF(AN3="","",AD3+AE3+AF3) | AH3: =IF(AN3="","",P3*(1-AG3)) | AI3: =IF(AN3="","",IF(Q3="Sin Factura",0,IFERROR(INDEX(Facturas_Odoo!$H:$H, MATCH(Q3, Facturas_Odoo!$B:$B, 0)), 0)*(1-AG3))) | AJ3: =IF(AN3="","",_xlfn.LET(idVenta, AN3&"", pagos, IFERROR(SUMIF(Aux_Datos!$B:$B, idVenta, Aux_Datos!$L:$L), 0), retenciones, IFERROR(SUMIF(Aux_Datos!$O:$O, idVenta, Aux_Datos!$S:$S), 0), pagos_manuales, IFERROR(SUMIF('Asignación Pagos'!$G:$G, idVenta, 'Asignación Pagos'!$F:$F), 0), pagos+retenciones+pagos_manuales)) | AK3: =IF(AN3="","",AH3-AJ3) | AL3: =IF(AN3="","",IF(Q3="Sin Factura","",AI3-AJ3)) | AM3: =IF(AN3="","",IF(Q3="Sin Factura",0,P3-IFERROR(INDEX(Facturas_Odoo!$H:$H, MATCH(Q3, Facturas_Odoo!$B:$B, 0)), 0))) | AN3: =IF(AND(A3="", J3=""), "", IF(A3<>"", VALUE(MID(A3,2,LEN(A3))), AN2)) | AO3: =IF(AN3="","",IF(AD3=0,"OK",_xlfn.LET(monedaPago, IF(AA3="","USD",AA3), limitePermitido, IFERROR(VLOOKUP(monedaPago, Configuración!$A$2:$B$3, 2, FALSE), 0.15), IF(AD3>limitePermitido, "ALERTA: EXCESO (" & TEXT(limitePermitido, "0%") & " máx)", "OK")))) | AP3: =IF(AN3="","",IF(AE3=0,"OK",_xlfn.LET(fechaPago, Z3, fechaFactura, R3, diasCredito, IF(E3="Pago inmediato", 0, IFERROR(VALUE(MID(E3, 1, SEARCH(" ", E3)-1)), 0)), tolerancia, Configuración!$E$2, limiteDias, diasCredito + tolerancia, IF(OR(fechaPago="", fechaFactura=""), "REVISAR: SIN FECHA", IF(fechaPago - fechaFactura > limiteDias, "ALERTA: PAGO FUERA DE PLAZO (" & (fechaPago - fechaFactura) & " días)", "OK"))))) | AQ3: =IF(AN3="","",IF(AND(N3>0, AG3>0), IF(Configuración!$K$2="NO", "ALERTA: DESCUENTO DOBLE NO PERMITIDO", "OK"), "OK")) | AR3: =IF(AN3="","",IF(OR(AO3<>"OK", AP3<>"OK", AQ3<>"OK"), "⚠️ REVISAR", "OK"))
A4: =IF('Ordenes_Odoo'!A4="","",'Ordenes_Odoo'!A4) | B4: =IF('Ordenes_Odoo'!B4="","",'Ordenes_Odoo'!B4) | C4: =IF('Ordenes_Odoo'!C4="","",'Ordenes_Odoo'!C4) | D4: =IF('Ordenes_Odoo'!D4="","",'Ordenes_Odoo'!D4) | E4: =IF('Ordenes_Odoo'!E4="","",'Ordenes_Odoo'!E4) | F4: =IF('Ordenes_Odoo'!F4="","",'Ordenes_Odoo'!F4) | G4: =IF('Ordenes_Odoo'!G4="","",'Ordenes_Odoo'!G4) | H4: =IF('Ordenes_Odoo'!H4="","",'Ordenes_Odoo'!H4) | ... P4: =IF('Ordenes_Odoo'!P4="","",'Ordenes_Odoo'!P4) | Q4: =IF(A4="","",IFERROR(INDEX(Facturas_Odoo!$B:$B, MATCH(A4, Facturas_Odoo!$D:$D, 0)), "Sin Factura")) | R4: =IF(Q4="Sin Factura","",IFERROR(INDEX(Facturas_Odoo!$A:$A, MATCH(Q4, Facturas_Odoo!$B:$B, 0)), "")) | S4: =IF(Q4="Sin Factura","",IFERROR(_xlfn.XLOOKUP(1, (Facturas_Odoo!$D:$D=A4) * (Facturas_Odoo!$K:$K=I4), Facturas_Odoo!$L:$L, ""), "")) | T4: =IF(Q4="Sin Factura",0,IFERROR(_xlfn.XLOOKUP(1, (Facturas_Odoo!$D:$D=A4) * (Facturas_Odoo!$K:$K=I4), Facturas_Odoo!$M:$M, 0), 0)) | U4: =IF(Q4="Sin Factura",0,IFERROR(_xlfn.XLOOKUP(1, (Facturas_Odoo!$D:$D=A4) * (Facturas_Odoo!$K:$K=I4), Facturas_Odoo!$N:$N, 0), 0)) | V4: =IF(Q4="Sin Factura",0,IFERROR(_xlfn.XLOOKUP(1, (Facturas_Odoo!$D:$D=A4) * (Facturas_Odoo!$K:$K=I4), Facturas_Odoo!$O:$O, 0), 0)) | W4: =IF(Q4="Sin Factura",0,IFERROR(_xlfn.XLOOKUP(1, (Facturas_Odoo!$D:$D=A4) * (Facturas_Odoo!$K:$K=I4), Facturas_Odoo!$Q:$Q, 0), 0)) | X4: =IF(OR(Q4="Sin Factura",Q4=""),"",IFERROR(INDEX(Pagos_Odoo!$B:$B, MATCH(Q4, Pagos_Odoo!$I:$I, 0)), "Sin Pago")) | Y4: =IF(X4="Sin Pago","",IFERROR(INDEX(Pagos_Odoo!$C:$C, MATCH(X4, Pagos_Odoo!$B:$B, 0)), "")) | Z4: =IF(X4="Sin Pago","",IFERROR(INDEX(Pagos_Odoo!$A:$A, MATCH(X4, Pagos_Odoo!$B:$B, 0)), "")) | AA4: =IF(X4="Sin Pago","",IFERROR(INDEX(Pagos_Odoo!$F:$F, MATCH(X4, Pagos_Odoo!$B:$B, 0)), "")) | AB4: =IF(X4="Sin Pago",0,IFERROR(INDEX(Pagos_Odoo!$E:$E, MATCH(X4, Pagos_Odoo!$B:$B, 0)), 0)) | AC4: =IF(X4="Sin Pago","",IFERROR(INDEX(Pagos_Odoo!$G:$G, MATCH(X4, Pagos_Odoo!$B:$B, 0)), "")) | AD4: 0 | AG4: =IF(AN4="","",AD4+AE4+AF4) | AH4: =IF(AN4="","",P4*(1-AG4)) | AI4: =IF(AN4="","",IF(Q4="Sin Factura",0,IFERROR(INDEX(Facturas_Odoo!$H:$H, MATCH(Q4, Facturas_Odoo!$B:$B, 0)), 0)*(1-AG4))) | AJ4: =IF(AN4="","",_xlfn.LET(idVenta, AN4&"", pagos, IFERROR(SUMIF(Aux_Datos!$B:$B, idVenta, Aux_Datos!$L:$L), 0), retenciones, IFERROR(SUMIF(Aux_Datos!$O:$O, idVenta, Aux_Datos!$S:$S), 0), pagos_manuales, IFERROR(SUMIF('Asignación Pagos'!$G:$G, idVenta, 'Asignación Pagos'!$F:$F), 0), pagos+retenciones+pagos_manuales)) | AK4: =IF(AN4="","",AH4-AJ4) | AL4: =IF(AN4="","",IF(Q4="Sin Factura","",AI4-AJ4)) | AM4: =IF(AN4="","",IF(Q4="Sin Factura",0,P4-IFERROR(INDEX(Facturas_Odoo!$H:$H, MATCH(Q4, Facturas_Odoo!$B:$B, 0)), 0))) | AN4: =IF(AND(A4="", J4=""), "", IF(A4<>"", VALUE(MID(A4,2,LEN(A4))), AN3)) | AO4: =IF(AN4="","",IF(AD4=0,"OK",_xlfn.LET(monedaPago, IF(AA4="","USD",AA4), limitePermitido, IFERROR(VLOOKUP(monedaPago, Configuración!$A$2:$B$3, 2, FALSE), 0.15), IF(AD4>limitePermitido, "ALERTA: EXCESO (" & TEXT(limitePermitido, "0%") & " máx)", "OK")))) | AP4: =IF(AN4="","",IF(AE4=0,"OK",_xlfn.LET(fechaPago, Z4, fechaFactura, R4, diasCredito, IF(E4="Pago inmediato", 0, IFERROR(VALUE(MID(E4, 1, SEARCH(" ", E4)-1)), 0)), tolerancia, Configuración!$E$2, limiteDias, diasCredito + tolerancia, IF(OR(fechaPago="", fechaFactura=""), "REVISAR: SIN FECHA", IF(fechaPago - fechaFactura > limiteDias, "ALERTA: PAGO FUERA DE PLAZO (" & (fechaPago - fechaFactura) & " días)", "OK"))))) | AQ4: =IF(AN4="","",IF(AND(N4>0, AG4>0), IF(Configuración!$K$2="NO", "ALERTA: DESCUENTO DOBLE NO PERMITIDO", "OK"), "OK")) | AR4: =IF(AN4="","",IF(OR(AO4<>"OK", AP4<>"OK", AQ4<>"OK"), "⚠️ REVISAR", "OK"))
A5: =IF('Ordenes_Odoo'!A5="","",'Ordenes_Odoo'!A5) | B5: =IF('Ordenes_Odoo'!B5="","",'Ordenes_Odoo'!B5) | C5: =IF('Ordenes_Odoo'!C5="","",'Ordenes_Odoo'!C5) | D5: =IF('Ordenes_Odoo'!D5="","",'Ordenes_Odoo'!D5) | E5: =IF('Ordenes_Odoo'!E5="","",'Ordenes_Odoo'!E5) | F5: =IF('Ordenes_Odoo'!F5="","",'Ordenes_Odoo'!F5) | G5: =IF('Ordenes_Odoo'!G5="","",'Ordenes_Odoo'!G5) | H5: =IF('Ordenes_Odoo'!H5="","",'Ordenes_Odoo'!H5) | ... P5: =IF('Ordenes_Odoo'!P5="","",'Ordenes_Odoo'!P5) | Q5: =IF(A5="","",IFERROR(INDEX(Facturas_Odoo!$B:$B, MATCH(A5, Facturas_Odoo!$D:$D, 0)), "Sin Factura")) | R5: =IF(Q5="Sin Factura","",IFERROR(INDEX(Facturas_Odoo!$A:$A, MATCH(Q5, Facturas_Odoo!$B:$B, 0)), "")) | S5: =IF(Q5="Sin Factura","",IFERROR(_xlfn.XLOOKUP(1, (Facturas_Odoo!$D:$D=A5) * (Facturas_Odoo!$K:$K=I5), Facturas_Odoo!$L:$L, ""), "")) | T5: =IF(Q5="Sin Factura",0,IFERROR(_xlfn.XLOOKUP(1, (Facturas_Odoo!$D:$D=A5) * (Facturas_Odoo!$K:$K=I5), Facturas_Odoo!$M:$M, 0), 0)) | U5: =IF(Q5="Sin Factura",0,IFERROR(_xlfn.XLOOKUP(1, (Facturas_Odoo!$D:$D=A5) * (Facturas_Odoo!$K:$K=I5), Facturas_Odoo!$N:$N, 0), 0)) | V5: =IF(Q5="Sin Factura",0,IFERROR(_xlfn.XLOOKUP(1, (Facturas_Odoo!$D:$D=A5) * (Facturas_Odoo!$K:$K=I5), Facturas_Odoo!$O:$O, 0), 0)) | W5: =IF(Q5="Sin Factura",0,IFERROR(_xlfn.XLOOKUP(1, (Facturas_Odoo!$D:$D=A5) * (Facturas_Odoo!$K:$K=I5), Facturas_Odoo!$Q:$Q, 0), 0)) | X5: =IF(OR(Q5="Sin Factura",Q5=""),"",IFERROR(INDEX(Pagos_Odoo!$B:$B, MATCH(Q5, Pagos_Odoo!$I:$I, 0)), "Sin Pago")) | Y5: =IF(X5="Sin Pago","",IFERROR(INDEX(Pagos_Odoo!$C:$C, MATCH(X5, Pagos_Odoo!$B:$B, 0)), "")) | Z5: =IF(X5="Sin Pago","",IFERROR(INDEX(Pagos_Odoo!$A:$A, MATCH(X5, Pagos_Odoo!$B:$B, 0)), "")) | AA5: =IF(X5="Sin Pago","",IFERROR(INDEX(Pagos_Odoo!$F:$F, MATCH(X5, Pagos_Odoo!$B:$B, 0)), "")) | AB5: =IF(X5="Sin Pago",0,IFERROR(INDEX(Pagos_Odoo!$E:$E, MATCH(X5, Pagos_Odoo!$B:$B, 0)), 0)) | AC5: =IF(X5="Sin Pago","",IFERROR(INDEX(Pagos_Odoo!$G:$G, MATCH(X5, Pagos_Odoo!$B:$B, 0)), "")) | AD5: 0 | AG5: =IF(AN5="","",AD5+AE5+AF5) | AH5: =IF(AN5="","",P5*(1-AG5)) | AI5: =IF(AN5="","",IF(Q5="Sin Factura",0,IFERROR(INDEX(Facturas_Odoo!$H:$H, MATCH(Q5, Facturas_Odoo!$B:$B, 0)), 0)*(1-AG5))) | AJ5: =IF(AN5="","",_xlfn.LET(idVenta, AN5&"", pagos, IFERROR(SUMIF(Aux_Datos!$B:$B, idVenta, Aux_Datos!$L:$L), 0), retenciones, IFERROR(SUMIF(Aux_Datos!$O:$O, idVenta, Aux_Datos!$S:$S), 0), pagos_manuales, IFERROR(SUMIF('Asignación Pagos'!$G:$G, idVenta, 'Asignación Pagos'!$F:$F), 0), pagos+retenciones+pagos_manuales)) | AK5: =IF(AN5="","",AH5-AJ5) | AL5: =IF(AN5="","",IF(Q5="Sin Factura","",AI5-AJ5)) | AM5: =IF(AN5="","",IF(Q5="Sin Factura",0,P5-IFERROR(INDEX(Facturas_Odoo!$H:$H, MATCH(Q5, Facturas_Odoo!$B:$B, 0)), 0))) | AN5: =IF(AND(A5="", J5=""), "", IF(A5<>"", VALUE(MID(A5,2,LEN(A5))), AN4)) | AO5: =IF(AN5="","",IF(AD5=0,"OK",_xlfn.LET(monedaPago, IF(AA5="","USD",AA5), limitePermitido, IFERROR(VLOOKUP(monedaPago, Configuración!$A$2:$B$3, 2, FALSE), 0.15), IF(AD5>limitePermitido, "ALERTA: EXCESO (" & TEXT(limitePermitido, "0%") & " máx)", "OK")))) | AP5: =IF(AN5="","",IF(AE5=0,"OK",_xlfn.LET(fechaPago, Z5, fechaFactura, R5, diasCredito, IF(E5="Pago inmediato", 0, IFERROR(VALUE(MID(E5, 1, SEARCH(" ", E5)-1)), 0)), tolerancia, Configuración!$E$2, limiteDias, diasCredito + tolerancia, IF(OR(fechaPago="", fechaFactura=""), "REVISAR: SIN FECHA", IF(fechaPago - fechaFactura > limiteDias, "ALERTA: PAGO FUERA DE PLAZO (" & (fechaPago - fechaFactura) & " días)", "OK"))))) | AQ5: =IF(AN5="","",IF(AND(N5>0, AG5>0), IF(Configuración!$K$2="NO", "ALERTA: DESCUENTO DOBLE NO PERMITIDO", "OK"), "OK")) | AR5: =IF(AN5="","",IF(OR(AO5<>"OK", AP5<>"OK", AQ5<>"OK"), "⚠️ REVISAR", "OK"))
A6: =IF('Ordenes_Odoo'!A6="","",'Ordenes_Odoo'!A6) | B6: =IF('Ordenes_Odoo'!B6="","",'Ordenes_Odoo'!B6) | C6: =IF('Ordenes_Odoo'!C6="","",'Ordenes_Odoo'!C6) | D6: =IF('Ordenes_Odoo'!D6="","",'Ordenes_Odoo'!D6) | E6: =IF('Ordenes_Odoo'!E6="","",'Ordenes_Odoo'!E6) | F6: =IF('Ordenes_Odoo'!F6="","",'Ordenes_Odoo'!F6) | G6: =IF('Ordenes_Odoo'!G6="","",'Ordenes_Odoo'!G6) | H6: =IF('Ordenes_Odoo'!H6="","",'Ordenes_Odoo'!H6) | ... P6: =IF('Ordenes_Odoo'!P6="","",'Ordenes_Odoo'!P6) | Q6: =IF(A6="","",IFERROR(INDEX(Facturas_Odoo!$B:$B, MATCH(A6, Facturas_Odoo!$D:$D, 0)), "Sin Factura")) | R6: =IF(Q6="Sin Factura","",IFERROR(INDEX(Facturas_Odoo!$A:$A, MATCH(Q6, Facturas_Odoo!$B:$B, 0)), "")) | S6: =IF(Q6="Sin Factura","",IFERROR(_xlfn.XLOOKUP(1, (Facturas_Odoo!$D:$D=A6) * (Facturas_Odoo!$K:$K=I6), Facturas_Odoo!$L:$L, ""), "")) | T6: =IF(Q6="Sin Factura",0,IFERROR(_xlfn.XLOOKUP(1, (Facturas_Odoo!$D:$D=A6) * (Facturas_Odoo!$K:$K=I6), Facturas_Odoo!$M:$M, 0), 0)) | U6: =IF(Q6="Sin Factura",0,IFERROR(_xlfn.XLOOKUP(1, (Facturas_Odoo!$D:$D=A6) * (Facturas_Odoo!$K:$K=I6), Facturas_Odoo!$N:$N, 0), 0)) | V6: =IF(Q6="Sin Factura",0,IFERROR(_xlfn.XLOOKUP(1, (Facturas_Odoo!$D:$D=A6) * (Facturas_Odoo!$K:$K=I6), Facturas_Odoo!$O:$O, 0), 0)) | W6: =IF(Q6="Sin Factura",0,IFERROR(_xlfn.XLOOKUP(1, (Facturas_Odoo!$D:$D=A6) * (Facturas_Odoo!$K:$K=I6), Facturas_Odoo!$Q:$Q, 0), 0)) | X6: =IF(OR(Q6="Sin Factura",Q6=""),"",IFERROR(INDEX(Pagos_Odoo!$B:$B, MATCH(Q6, Pagos_Odoo!$I:$I, 0)), "Sin Pago")) | Y6: =IF(X6="Sin Pago","",IFERROR(INDEX(Pagos_Odoo!$C:$C, MATCH(X6, Pagos_Odoo!$B:$B, 0)), "")) | Z6: =IF(X6="Sin Pago","",IFERROR(INDEX(Pagos_Odoo!$A:$A, MATCH(X6, Pagos_Odoo!$B:$B, 0)), "")) | AA6: =IF(X6="Sin Pago","",IFERROR(INDEX(Pagos_Odoo!$F:$F, MATCH(X6, Pagos_Odoo!$B:$B, 0)), "")) | AB6: =IF(X6="Sin Pago",0,IFERROR(INDEX(Pagos_Odoo!$E:$E, MATCH(X6, Pagos_Odoo!$B:$B, 0)), 0)) | AC6: =IF(X6="Sin Pago","",IFERROR(INDEX(Pagos_Odoo!$G:$G, MATCH(X6, Pagos_Odoo!$B:$B, 0)), "")) | AD6: 0 | AG6: =IF(AN6="","",AD6+AE6+AF6) | AH6: =IF(AN6="","",P6*(1-AG6)) | AI6: =IF(AN6="","",IF(Q6="Sin Factura",0,IFERROR(INDEX(Facturas_Odoo!$H:$H, MATCH(Q6, Facturas_Odoo!$B:$B, 0)), 0)*(1-AG6))) | AJ6: =IF(AN6="","",_xlfn.LET(idVenta, AN6&"", pagos, IFERROR(SUMIF(Aux_Datos!$B:$B, idVenta, Aux_Datos!$L:$L), 0), retenciones, IFERROR(SUMIF(Aux_Datos!$O:$O, idVenta, Aux_Datos!$S:$S), 0), pagos_manuales, IFERROR(SUMIF('Asignación Pagos'!$G:$G, idVenta, 'Asignación Pagos'!$F:$F), 0), pagos+retenciones+pagos_manuales)) | AK6: =IF(AN6="","",AH6-AJ6) | AL6: =IF(AN6="","",IF(Q6="Sin Factura","",AI6-AJ6)) | AM6: =IF(AN6="","",IF(Q6="Sin Factura",0,P6-IFERROR(INDEX(Facturas_Odoo!$H:$H, MATCH(Q6, Facturas_Odoo!$B:$B, 0)), 0))) | AN6: =IF(AND(A6="", J6=""), "", IF(A6<>"", VALUE(MID(A6,2,LEN(A6))), AN5)) | AO6: =IF(AN6="","",IF(AD6=0,"OK",_xlfn.LET(monedaPago, IF(AA6="","USD",AA6), limitePermitido, IFERROR(VLOOKUP(monedaPago, Configuración!$A$2:$B$3, 2, FALSE), 0.15), IF(AD6>limitePermitido, "ALERTA: EXCESO (" & TEXT(limitePermitido, "0%") & " máx)", "OK")))) | AP6: =IF(AN6="","",IF(AE6=0,"OK",_xlfn.LET(fechaPago, Z6, fechaFactura, R6, diasCredito, IF(E6="Pago inmediato", 0, IFERROR(VALUE(MID(E6, 1, SEARCH(" ", E6)-1)), 0)), tolerancia, Configuración!$E$2, limiteDias, diasCredito + tolerancia, IF(OR(fechaPago="", fechaFactura=""), "REVISAR: SIN FECHA", IF(fechaPago - fechaFactura > limiteDias, "ALERTA: PAGO FUERA DE PLAZO (" & (fechaPago - fechaFactura) & " días)", "OK"))))) | AQ6: =IF(AN6="","",IF(AND(N6>0, AG6>0), IF(Configuración!$K$2="NO", "ALERTA: DESCUENTO DOBLE NO PERMITIDO", "OK"), "OK")) | AR6: =IF(AN6="","",IF(OR(AO6<>"OK", AP6<>"OK", AQ6<>"OK"), "⚠️ REVISAR", "OK"))
A7: =IF('Ordenes_Odoo'!A7="","",'Ordenes_Odoo'!A7) | B7: =IF('Ordenes_Odoo'!B7="","",'Ordenes_Odoo'!B7) | C7: =IF('Ordenes_Odoo'!C7="","",'Ordenes_Odoo'!C7) | D7: =IF('Ordenes_Odoo'!D7="","",'Ordenes_Odoo'!D7) | E7: =IF('Ordenes_Odoo'!E7="","",'Ordenes_Odoo'!E7) | F7: =IF('Ordenes_Odoo'!F7="","",'Ordenes_Odoo'!F7) | G7: =IF('Ordenes_Odoo'!G7="","",'Ordenes_Odoo'!G7) | H7: =IF('Ordenes_Odoo'!H7="","",'Ordenes_Odoo'!H7) | ... P7: =IF('Ordenes_Odoo'!P7="","",'Ordenes_Odoo'!P7) | Q7: =IF(A7="","",IFERROR(INDEX(Facturas_Odoo!$B:$B, MATCH(A7, Facturas_Odoo!$D:$D, 0)), "Sin Factura")) | R7: =IF(Q7="Sin Factura","",IFERROR(INDEX(Facturas_Odoo!$A:$A, MATCH(Q7, Facturas_Odoo!$B:$B, 0)), "")) | S7: =IF(Q7="Sin Factura","",IFERROR(_xlfn.XLOOKUP(1, (Facturas_Odoo!$D:$D=A7) * (Facturas_Odoo!$K:$K=I7), Facturas_Odoo!$L:$L, ""), "")) | T7: =IF(Q7="Sin Factura",0,IFERROR(_xlfn.XLOOKUP(1, (Facturas_Odoo!$D:$D=A7) * (Facturas_Odoo!$K:$K=I7), Facturas_Odoo!$M:$M, 0), 0)) | U7: =IF(Q7="Sin Factura",0,IFERROR(_xlfn.XLOOKUP(1, (Facturas_Odoo!$D:$D=A7) * (Facturas_Odoo!$K:$K=I7), Facturas_Odoo!$N:$N, 0), 0)) | V7: =IF(Q7="Sin Factura",0,IFERROR(_xlfn.XLOOKUP(1, (Facturas_Odoo!$D:$D=A7) * (Facturas_Odoo!$K:$K=I7), Facturas_Odoo!$O:$O, 0), 0)) | W7: =IF(Q7="Sin Factura",0,IFERROR(_xlfn.XLOOKUP(1, (Facturas_Odoo!$D:$D=A7) * (Facturas_Odoo!$K:$K=I7), Facturas_Odoo!$Q:$Q, 0), 0)) | X7: =IF(OR(Q7="Sin Factura",Q7=""),"",IFERROR(INDEX(Pagos_Odoo!$B:$B, MATCH(Q7, Pagos_Odoo!$I:$I, 0)), "Sin Pago")) | Y7: =IF(X7="Sin Pago","",IFERROR(INDEX(Pagos_Odoo!$C:$C, MATCH(X7, Pagos_Odoo!$B:$B, 0)), "")) | Z7: =IF(X7="Sin Pago","",IFERROR(INDEX(Pagos_Odoo!$A:$A, MATCH(X7, Pagos_Odoo!$B:$B, 0)), "")) | AA7: =IF(X7="Sin Pago","",IFERROR(INDEX(Pagos_Odoo!$F:$F, MATCH(X7, Pagos_Odoo!$B:$B, 0)), "")) | AB7: =IF(X7="Sin Pago",0,IFERROR(INDEX(Pagos_Odoo!$E:$E, MATCH(X7, Pagos_Odoo!$B:$B, 0)), 0)) | AC7: =IF(X7="Sin Pago","",IFERROR(INDEX(Pagos_Odoo!$G:$G, MATCH(X7, Pagos_Odoo!$B:$B, 0)), "")) | AD7: 0 | AG7: =IF(AN7="","",AD7+AE7+AF7) | AH7: =IF(AN7="","",P7*(1-AG7)) | AI7: =IF(AN7="","",IF(Q7="Sin Factura",0,IFERROR(INDEX(Facturas_Odoo!$H:$H, MATCH(Q7, Facturas_Odoo!$B:$B, 0)), 0)*(1-AG7))) | AJ7: =IF(AN7="","",_xlfn.LET(idVenta, AN7&"", pagos, IFERROR(SUMIF(Aux_Datos!$B:$B, idVenta, Aux_Datos!$L:$L), 0), retenciones, IFERROR(SUMIF(Aux_Datos!$O:$O, idVenta, Aux_Datos!$S:$S), 0), pagos_manuales, IFERROR(SUMIF('Asignación Pagos'!$G:$G, idVenta, 'Asignación Pagos'!$F:$F), 0), pagos+retenciones+pagos_manuales)) | AK7: =IF(AN7="","",AH7-AJ7) | AL7: =IF(AN7="","",IF(Q7="Sin Factura","",AI7-AJ7)) | AM7: =IF(AN7="","",IF(Q7="Sin Factura",0,P7-IFERROR(INDEX(Facturas_Odoo!$H:$H, MATCH(Q7, Facturas_Odoo!$B:$B, 0)), 0))) | AN7: =IF(AND(A7="", J7=""), "", IF(A7<>"", VALUE(MID(A7,2,LEN(A7))), AN6)) | AO7: =IF(AN7="","",IF(AD7=0,"OK",_xlfn.LET(monedaPago, IF(AA7="","USD",AA7), limitePermitido, IFERROR(VLOOKUP(monedaPago, Configuración!$A$2:$B$3, 2, FALSE), 0.15), IF(AD7>limitePermitido, "ALERTA: EXCESO (" & TEXT(limitePermitido, "0%") & " máx)", "OK")))) | AP7: =IF(AN7="","",IF(AE7=0,"OK",_xlfn.LET(fechaPago, Z7, fechaFactura, R7, diasCredito, IF(E7="Pago inmediato", 0, IFERROR(VALUE(MID(E7, 1, SEARCH(" ", E7)-1)), 0)), tolerancia, Configuración!$E$2, limiteDias, diasCredito + tolerancia, IF(OR(fechaPago="", fechaFactura=""), "REVISAR: SIN FECHA", IF(fechaPago - fechaFactura > limiteDias, "ALERTA: PAGO FUERA DE PLAZO (" & (fechaPago - fechaFactura) & " días)", "OK"))))) | AQ7: =IF(AN7="","",IF(AND(N7>0, AG7>0), IF(Configuración!$K$2="NO", "ALERTA: DESCUENTO DOBLE NO PERMITIDO", "OK"), "OK")) | AR7: =IF(AN7="","",IF(OR(AO7<>"OK", AP7<>"OK", AQ7<>"OK"), "⚠️ REVISAR", "OK"))
A8: =IF('Ordenes_Odoo'!A8="","",'Ordenes_Odoo'!A8) | B8: =IF('Ordenes_Odoo'!B8="","",'Ordenes_Odoo'!B8) | C8: =IF('Ordenes_Odoo'!C8="","",'Ordenes_Odoo'!C8) | D8: =IF('Ordenes_Odoo'!D8="","",'Ordenes_Odoo'!D8) | E8: =IF('Ordenes_Odoo'!E8="","",'Ordenes_Odoo'!E8) | F8: =IF('Ordenes_Odoo'!F8="","",'Ordenes_Odoo'!F8) | G8: =IF('Ordenes_Odoo'!G8="","",'Ordenes_Odoo'!G8) | H8: =IF('Ordenes_Odoo'!H8="","",'Ordenes_Odoo'!H8) | ... P8: =IF('Ordenes_Odoo'!P8="","",'Ordenes_Odoo'!P8) | Q8: =IF(A8="","",IFERROR(INDEX(Facturas_Odoo!$B:$B, MATCH(A8, Facturas_Odoo!$D:$D, 0)), "Sin Factura")) | R8: =IF(Q8="Sin Factura","",IFERROR(INDEX(Facturas_Odoo!$A:$A, MATCH(Q8, Facturas_Odoo!$B:$B, 0)), "")) | S8: =IF(Q8="Sin Factura","",IFERROR(_xlfn.XLOOKUP(1, (Facturas_Odoo!$D:$D=A8) * (Facturas_Odoo!$K:$K=I8), Facturas_Odoo!$L:$L, ""), "")) | T8: =IF(Q8="Sin Factura",0,IFERROR(_xlfn.XLOOKUP(1, (Facturas_Odoo!$D:$D=A8) * (Facturas_Odoo!$K:$K=I8), Facturas_Odoo!$M:$M, 0), 0)) | U8: =IF(Q8="Sin Factura",0,IFERROR(_xlfn.XLOOKUP(1, (Facturas_Odoo!$D:$D=A8) * (Facturas_Odoo!$K:$K=I8), Facturas_Odoo!$N:$N, 0), 0)) | V8: =IF(Q8="Sin Factura",0,IFERROR(_xlfn.XLOOKUP(1, (Facturas_Odoo!$D:$D=A8) * (Facturas_Odoo!$K:$K=I8), Facturas_Odoo!$O:$O, 0), 0)) | W8: =IF(Q8="Sin Factura",0,IFERROR(_xlfn.XLOOKUP(1, (Facturas_Odoo!$D:$D=A8) * (Facturas_Odoo!$K:$K=I8), Facturas_Odoo!$Q:$Q, 0), 0)) | X8: =IF(OR(Q8="Sin Factura",Q8=""),"",IFERROR(INDEX(Pagos_Odoo!$B:$B, MATCH(Q8, Pagos_Odoo!$I:$I, 0)), "Sin Pago")) | Y8: =IF(X8="Sin Pago","",IFERROR(INDEX(Pagos_Odoo!$C:$C, MATCH(X8, Pagos_Odoo!$B:$B, 0)), "")) | Z8: =IF(X8="Sin Pago","",IFERROR(INDEX(Pagos_Odoo!$A:$A, MATCH(X8, Pagos_Odoo!$B:$B, 0)), "")) | AA8: =IF(X8="Sin Pago","",IFERROR(INDEX(Pagos_Odoo!$F:$F, MATCH(X8, Pagos_Odoo!$B:$B, 0)), "")) | AB8: =IF(X8="Sin Pago",0,IFERROR(INDEX(Pagos_Odoo!$E:$E, MATCH(X8, Pagos_Odoo!$B:$B, 0)), 0)) | AC8: =IF(X8="Sin Pago","",IFERROR(INDEX(Pagos_Odoo!$G:$G, MATCH(X8, Pagos_Odoo!$B:$B, 0)), "")) | AD8: 0 | AG8: =IF(AN8="","",AD8+AE8+AF8) | AH8: =IF(AN8="","",P8*(1-AG8)) | AI8: =IF(AN8="","",IF(Q8="Sin Factura",0,IFERROR(INDEX(Facturas_Odoo!$H:$H, MATCH(Q8, Facturas_Odoo!$B:$B, 0)), 0)*(1-AG8))) | AJ8: =IF(AN8="","",_xlfn.LET(idVenta, AN8&"", pagos, IFERROR(SUMIF(Aux_Datos!$B:$B, idVenta, Aux_Datos!$L:$L), 0), retenciones, IFERROR(SUMIF(Aux_Datos!$O:$O, idVenta, Aux_Datos!$S:$S), 0), pagos_manuales, IFERROR(SUMIF('Asignación Pagos'!$G:$G, idVenta, 'Asignación Pagos'!$F:$F), 0), pagos+retenciones+pagos_manuales)) | AK8: =IF(AN8="","",AH8-AJ8) | AL8: =IF(AN8="","",IF(Q8="Sin Factura","",AI8-AJ8)) | AM8: =IF(AN8="","",IF(Q8="Sin Factura",0,P8-IFERROR(INDEX(Facturas_Odoo!$H:$H, MATCH(Q8, Facturas_Odoo!$B:$B, 0)), 0))) | AN8: =IF(AND(A8="", J8=""), "", IF(A8<>"", VALUE(MID(A8,2,LEN(A8))), AN7)) | AO8: =IF(AN8="","",IF(AD8=0,"OK",_xlfn.LET(monedaPago, IF(AA8="","USD",AA8), limitePermitido, IFERROR(VLOOKUP(monedaPago, Configuración!$A$2:$B$3, 2, FALSE), 0.15), IF(AD8>limitePermitido, "ALERTA: EXCESO (" & TEXT(limitePermitido, "0%") & " máx)", "OK")))) | AP8: =IF(AN8="","",IF(AE8=0,"OK",_xlfn.LET(fechaPago, Z8, fechaFactura, R8, diasCredito, IF(E8="Pago inmediato", 0, IFERROR(VALUE(MID(E8, 1, SEARCH(" ", E8)-1)), 0)), tolerancia, Configuración!$E$2, limiteDias, diasCredito + tolerancia, IF(OR(fechaPago="", fechaFactura=""), "REVISAR: SIN FECHA", IF(fechaPago - fechaFactura > limiteDias, "ALERTA: PAGO FUERA DE PLAZO (" & (fechaPago - fechaFactura) & " días)", "OK"))))) | AQ8: =IF(AN8="","",IF(AND(N8>0, AG8>0), IF(Configuración!$K$2="NO", "ALERTA: DESCUENTO DOBLE NO PERMITIDO", "OK"), "OK")) | AR8: =IF(AN8="","",IF(OR(AO8<>"OK", AP8<>"OK", AQ8<>"OK"), "⚠️ REVISAR", "OK"))
A9: =IF('Ordenes_Odoo'!A9="","",'Ordenes_Odoo'!A9) | B9: =IF('Ordenes_Odoo'!B9="","",'Ordenes_Odoo'!B9) | C9: =IF('Ordenes_Odoo'!C9="","",'Ordenes_Odoo'!C9) | D9: =IF('Ordenes_Odoo'!D9="","",'Ordenes_Odoo'!D9) | E9: =IF('Ordenes_Odoo'!E9="","",'Ordenes_Odoo'!E9) | F9: =IF('Ordenes_Odoo'!F9="","",'Ordenes_Odoo'!F9) | G9: =IF('Ordenes_Odoo'!G9="","",'Ordenes_Odoo'!G9) | H9: =IF('Ordenes_Odoo'!H9="","",'Ordenes_Odoo'!H9) | ... P9: =IF('Ordenes_Odoo'!P9="","",'Ordenes_Odoo'!P9) | Q9: =IF(A9="","",IFERROR(INDEX(Facturas_Odoo!$B:$B, MATCH(A9, Facturas_Odoo!$D:$D, 0)), "Sin Factura")) | R9: =IF(Q9="Sin Factura","",IFERROR(INDEX(Facturas_Odoo!$A:$A, MATCH(Q9, Facturas_Odoo!$B:$B, 0)), "")) | S9: =IF(Q9="Sin Factura","",IFERROR(_xlfn.XLOOKUP(1, (Facturas_Odoo!$D:$D=A9) * (Facturas_Odoo!$K:$K=I9), Facturas_Odoo!$L:$L, ""), "")) | T9: =IF(Q9="Sin Factura",0,IFERROR(_xlfn.XLOOKUP(1, (Facturas_Odoo!$D:$D=A9) * (Facturas_Odoo!$K:$K=I9), Facturas_Odoo!$M:$M, 0), 0)) | U9: =IF(Q9="Sin Factura",0,IFERROR(_xlfn.XLOOKUP(1, (Facturas_Odoo!$D:$D=A9) * (Facturas_Odoo!$K:$K=I9), Facturas_Odoo!$N:$N, 0), 0)) | V9: =IF(Q9="Sin Factura",0,IFERROR(_xlfn.XLOOKUP(1, (Facturas_Odoo!$D:$D=A9) * (Facturas_Odoo!$K:$K=I9), Facturas_Odoo!$O:$O, 0), 0)) | W9: =IF(Q9="Sin Factura",0,IFERROR(_xlfn.XLOOKUP(1, (Facturas_Odoo!$D:$D=A9) * (Facturas_Odoo!$K:$K=I9), Facturas_Odoo!$Q:$Q, 0), 0)) | X9: =IF(OR(Q9="Sin Factura",Q9=""),"",IFERROR(INDEX(Pagos_Odoo!$B:$B, MATCH(Q9, Pagos_Odoo!$I:$I, 0)), "Sin Pago")) | Y9: =IF(X9="Sin Pago","",IFERROR(INDEX(Pagos_Odoo!$C:$C, MATCH(X9, Pagos_Odoo!$B:$B, 0)), "")) | Z9: =IF(X9="Sin Pago","",IFERROR(INDEX(Pagos_Odoo!$A:$A, MATCH(X9, Pagos_Odoo!$B:$B, 0)), "")) | AA9: =IF(X9="Sin Pago","",IFERROR(INDEX(Pagos_Odoo!$F:$F, MATCH(X9, Pagos_Odoo!$B:$B, 0)), "")) | AB9: =IF(X9="Sin Pago",0,IFERROR(INDEX(Pagos_Odoo!$E:$E, MATCH(X9, Pagos_Odoo!$B:$B, 0)), 0)) | AC9: =IF(X9="Sin Pago","",IFERROR(INDEX(Pagos_Odoo!$G:$G, MATCH(X9, Pagos_Odoo!$B:$B, 0)), "")) | AD9: 0 | AG9: =IF(AN9="","",AD9+AE9+AF9) | AH9: =IF(AN9="","",P9*(1-AG9)) | AI9: =IF(AN9="","",IF(Q9="Sin Factura",0,IFERROR(INDEX(Facturas_Odoo!$H:$H, MATCH(Q9, Facturas_Odoo!$B:$B, 0)), 0)*(1-AG9))) | AJ9: =IF(AN9="","",_xlfn.LET(idVenta, AN9&"", pagos, IFERROR(SUMIF(Aux_Datos!$B:$B, idVenta, Aux_Datos!$L:$L), 0), retenciones, IFERROR(SUMIF(Aux_Datos!$O:$O, idVenta, Aux_Datos!$S:$S), 0), pagos_manuales, IFERROR(SUMIF('Asignación Pagos'!$G:$G, idVenta, 'Asignación Pagos'!$F:$F), 0), pagos+retenciones+pagos_manuales)) | AK9: =IF(AN9="","",AH9-AJ9) | AL9: =IF(AN9="","",IF(Q9="Sin Factura","",AI9-AJ9)) | AM9: =IF(AN9="","",IF(Q9="Sin Factura",0,P9-IFERROR(INDEX(Facturas_Odoo!$H:$H, MATCH(Q9, Facturas_Odoo!$B:$B, 0)), 0))) | AN9: =IF(AND(A9="", J9=""), "", IF(A9<>"", VALUE(MID(A9,2,LEN(A9))), AN8)) | AO9: =IF(AN9="","",IF(AD9=0,"OK",_xlfn.LET(monedaPago, IF(AA9="","USD",AA9), limitePermitido, IFERROR(VLOOKUP(monedaPago, Configuración!$A$2:$B$3, 2, FALSE), 0.15), IF(AD9>limitePermitido, "ALERTA: EXCESO (" & TEXT(limitePermitido, "0%") & " máx)", "OK")))) | AP9: =IF(AN9="","",IF(AE9=0,"OK",_xlfn.LET(fechaPago, Z9, fechaFactura, R9, diasCredito, IF(E9="Pago inmediato", 0, IFERROR(VALUE(MID(E9, 1, SEARCH(" ", E9)-1)), 0)), tolerancia, Configuración!$E$2, limiteDias, diasCredito + tolerancia, IF(OR(fechaPago="", fechaFactura=""), "REVISAR: SIN FECHA", IF(fechaPago - fechaFactura > limiteDias, "ALERTA: PAGO FUERA DE PLAZO (" & (fechaPago - fechaFactura) & " días)", "OK"))))) | AQ9: =IF(AN9="","",IF(AND(N9>0, AG9>0), IF(Configuración!$K$2="NO", "ALERTA: DESCUENTO DOBLE NO PERMITIDO", "OK"), "OK")) | AR9: =IF(AN9="","",IF(OR(AO9<>"OK", AP9<>"OK", AQ9<>"OK"), "⚠️ REVISAR", "OK"))
A10: =IF('Ordenes_Odoo'!A10="","",'Ordenes_Odoo'!A10) | B10: =IF('Ordenes_Odoo'!B10="","",'Ordenes_Odoo'!B10) | C10: =IF('Ordenes_Odoo'!C10="","",'Ordenes_Odoo'!C10) | D10: =IF('Ordenes_Odoo'!D10="","",'Ordenes_Odoo'!D10) | E10: =IF('Ordenes_Odoo'!E10="","",'Ordenes_Odoo'!E10) | F10: =IF('Ordenes_Odoo'!F10="","",'Ordenes_Odoo'!F10) | G10: =IF('Ordenes_Odoo'!G10="","",'Ordenes_Odoo'!G10) | H10: =IF('Ordenes_Odoo'!H10="","",'Ordenes_Odoo'!H10) | ... P10: =IF('Ordenes_Odoo'!P10="","",'Ordenes_Odoo'!P10) | Q10: =IF(A10="","",IFERROR(INDEX(Facturas_Odoo!$B:$B, MATCH(A10, Facturas_Odoo!$D:$D, 0)), "Sin Factura")) | R10: =IF(Q10="Sin Factura","",IFERROR(INDEX(Facturas_Odoo!$A:$A, MATCH(Q10, Facturas_Odoo!$B:$B, 0)), "")) | S10: =IF(Q10="Sin Factura","",IFERROR(_xlfn.XLOOKUP(1, (Facturas_Odoo!$D:$D=A10) * (Facturas_Odoo!$K:$K=I10), Facturas_Odoo!$L:$L, ""), "")) | T10: =IF(Q10="Sin Factura",0,IFERROR(_xlfn.XLOOKUP(1, (Facturas_Odoo!$D:$D=A10) * (Facturas_Odoo!$K:$K=I10), Facturas_Odoo!$M:$M, 0), 0)) | U10: =IF(Q10="Sin Factura",0,IFERROR(_xlfn.XLOOKUP(1, (Facturas_Odoo!$D:$D=A10) * (Facturas_Odoo!$K:$K=I10), Facturas_Odoo!$N:$N, 0), 0)) | V10: =IF(Q10="Sin Factura",0,IFERROR(_xlfn.XLOOKUP(1, (Facturas_Odoo!$D:$D=A10) * (Facturas_Odoo!$K:$K=I10), Facturas_Odoo!$O:$O, 0), 0)) | W10: =IF(Q10="Sin Factura",0,IFERROR(_xlfn.XLOOKUP(1, (Facturas_Odoo!$D:$D=A10) * (Facturas_Odoo!$K:$K=I10), Facturas_Odoo!$Q:$Q, 0), 0)) | X10: =IF(OR(Q10="Sin Factura",Q10=""),"",IFERROR(INDEX(Pagos_Odoo!$B:$B, MATCH(Q10, Pagos_Odoo!$I:$I, 0)), "Sin Pago")) | Y10: =IF(X10="Sin Pago","",IFERROR(INDEX(Pagos_Odoo!$C:$C, MATCH(X10, Pagos_Odoo!$B:$B, 0)), "")) | Z10: =IF(X10="Sin Pago","",IFERROR(INDEX(Pagos_Odoo!$A:$A, MATCH(X10, Pagos_Odoo!$B:$B, 0)), "")) | AA10: =IF(X10="Sin Pago","",IFERROR(INDEX(Pagos_Odoo!$F:$F, MATCH(X10, Pagos_Odoo!$B:$B, 0)), "")) | AB10: =IF(X10="Sin Pago",0,IFERROR(INDEX(Pagos_Odoo!$E:$E, MATCH(X10, Pagos_Odoo!$B:$B, 0)), 0)) | AC10: =IF(X10="Sin Pago","",IFERROR(INDEX(Pagos_Odoo!$G:$G, MATCH(X10, Pagos_Odoo!$B:$B, 0)), "")) | AD10: 0 | AG10: =IF(AN10="","",AD10+AE10+AF10) | AH10: =IF(AN10="","",P10*(1-AG10)) | AI10: =IF(AN10="","",IF(Q10="Sin Factura",0,IFERROR(INDEX(Facturas_Odoo!$H:$H, MATCH(Q10, Facturas_Odoo!$B:$B, 0)), 0)*(1-AG10))) | AJ10: =IF(AN10="","",_xlfn.LET(idVenta, AN10&"", pagos, IFERROR(SUMIF(Aux_Datos!$B:$B, idVenta, Aux_Datos!$L:$L), 0), retenciones, IFERROR(SUMIF(Aux_Datos!$O:$O, idVenta, Aux_Datos!$S:$S), 0), pagos_manuales, IFERROR(SUMIF('Asignación Pagos'!$G:$G, idVenta, 'Asignación Pagos'!$F:$F), 0), pagos+retenciones+pagos_manuales)) | AK10: =IF(AN10="","",AH10-AJ10) | AL10: =IF(AN10="","",IF(Q10="Sin Factura","",AI10-AJ10)) | AM10: =IF(AN10="","",IF(Q10="Sin Factura",0,P10-IFERROR(INDEX(Facturas_Odoo!$H:$H, MATCH(Q10, Facturas_Odoo!$B:$B, 0)), 0))) | AN10: =IF(AND(A10="", J10=""), "", IF(A10<>"", VALUE(MID(A10,2,LEN(A10))), AN9)) | AO10: =IF(AN10="","",IF(AD10=0,"OK",_xlfn.LET(monedaPago, IF(AA10="","USD",AA10), limitePermitido, IFERROR(VLOOKUP(monedaPago, Configuración!$A$2:$B$3, 2, FALSE), 0.15), IF(AD10>limitePermitido, "ALERTA: EXCESO (" & TEXT(limitePermitido, "0%") & " máx)", "OK")))) | AP10: =IF(AN10="","",IF(AE10=0,"OK",_xlfn.LET(fechaPago, Z10, fechaFactura, R10, diasCredito, IF(E10="Pago inmediato", 0, IFERROR(VALUE(MID(E10, 1, SEARCH(" ", E10)-1)), 0)), tolerancia, Configuración!$E$2, limiteDias, diasCredito + tolerancia, IF(OR(fechaPago="", fechaFactura=""), "REVISAR: SIN FECHA", IF(fechaPago - fechaFactura > limiteDias, "ALERTA: PAGO FUERA DE PLAZO (" & (fechaPago - fechaFactura) & " días)", "OK"))))) | AQ10: =IF(AN10="","",IF(AND(N10>0, AG10>0), IF(Configuración!$K$2="NO", "ALERTA: DESCUENTO DOBLE NO PERMITIDO", "OK"), "OK")) | AR10: =IF(AN10="","",IF(OR(AO10<>"OK", AP10<>"OK", AQ10<>"OK"), "⚠️ REVISAR", "OK"))
A11: =IF('Ordenes_Odoo'!A11="","",'Ordenes_Odoo'!A11) | B11: =IF('Ordenes_Odoo'!B11="","",'Ordenes_Odoo'!B11) | C11: =IF('Ordenes_Odoo'!C11="","",'Ordenes_Odoo'!C11) | D11: =IF('Ordenes_Odoo'!D11="","",'Ordenes_Odoo'!D11) | E11: =IF('Ordenes_Odoo'!E11="","",'Ordenes_Odoo'!E11) | F11: =IF('Ordenes_Odoo'!F11="","",'Ordenes_Odoo'!F11) | G11: =IF('Ordenes_Odoo'!G11="","",'Ordenes_Odoo'!G11) | H11: =IF('Ordenes_Odoo'!H11="","",'Ordenes_Odoo'!H11) | ... P11: =IF('Ordenes_Odoo'!P11="","",'Ordenes_Odoo'!P11) | Q11: =IF(A11="","",IFERROR(INDEX(Facturas_Odoo!$B:$B, MATCH(A11, Facturas_Odoo!$D:$D, 0)), "Sin Factura")) | R11: =IF(Q11="Sin Factura","",IFERROR(INDEX(Facturas_Odoo!$A:$A, MATCH(Q11, Facturas_Odoo!$B:$B, 0)), "")) | S11: =IF(Q11="Sin Factura","",IFERROR(_xlfn.XLOOKUP(1, (Facturas_Odoo!$D:$D=A11) * (Facturas_Odoo!$K:$K=I11), Facturas_Odoo!$L:$L, ""), "")) | T11: =IF(Q11="Sin Factura",0,IFERROR(_xlfn.XLOOKUP(1, (Facturas_Odoo!$D:$D=A11) * (Facturas_Odoo!$K:$K=I11), Facturas_Odoo!$M:$M, 0), 0)) | U11: =IF(Q11="Sin Factura",0,IFERROR(_xlfn.XLOOKUP(1, (Facturas_Odoo!$D:$D=A11) * (Facturas_Odoo!$K:$K=I11), Facturas_Odoo!$N:$N, 0), 0)) | V11: =IF(Q11="Sin Factura",0,IFERROR(_xlfn.XLOOKUP(1, (Facturas_Odoo!$D:$D=A11) * (Facturas_Odoo!$K:$K=I11), Facturas_Odoo!$O:$O, 0), 0)) | W11: =IF(Q11="Sin Factura",0,IFERROR(_xlfn.XLOOKUP(1, (Facturas_Odoo!$D:$D=A11) * (Facturas_Odoo!$K:$K=I11), Facturas_Odoo!$Q:$Q, 0), 0)) | X11: =IF(OR(Q11="Sin Factura",Q11=""),"",IFERROR(INDEX(Pagos_Odoo!$B:$B, MATCH(Q11, Pagos_Odoo!$I:$I, 0)), "Sin Pago")) | Y11: =IF(X11="Sin Pago","",IFERROR(INDEX(Pagos_Odoo!$C:$C, MATCH(X11, Pagos_Odoo!$B:$B, 0)), "")) | Z11: =IF(X11="Sin Pago","",IFERROR(INDEX(Pagos_Odoo!$A:$A, MATCH(X11, Pagos_Odoo!$B:$B, 0)), "")) | AA11: =IF(X11="Sin Pago","",IFERROR(INDEX(Pagos_Odoo!$F:$F, MATCH(X11, Pagos_Odoo!$B:$B, 0)), "")) | AB11: =IF(X11="Sin Pago",0,IFERROR(INDEX(Pagos_Odoo!$E:$E, MATCH(X11, Pagos_Odoo!$B:$B, 0)), 0)) | AC11: =IF(X11="Sin Pago","",IFERROR(INDEX(Pagos_Odoo!$G:$G, MATCH(X11, Pagos_Odoo!$B:$B, 0)), "")) | AD11: 0 | AG11: =IF(AN11="","",AD11+AE11+AF11) | AH11: =IF(AN11="","",P11*(1-AG11)) | AI11: =IF(AN11="","",IF(Q11="Sin Factura",0,IFERROR(INDEX(Facturas_Odoo!$H:$H, MATCH(Q11, Facturas_Odoo!$B:$B, 0)), 0)*(1-AG11))) | AJ11: =IF(AN11="","",_xlfn.LET(idVenta, AN11&"", pagos, IFERROR(SUMIF(Aux_Datos!$B:$B, idVenta, Aux_Datos!$L:$L), 0), retenciones, IFERROR(SUMIF(Aux_Datos!$O:$O, idVenta, Aux_Datos!$S:$S), 0), pagos_manuales, IFERROR(SUMIF('Asignación Pagos'!$G:$G, idVenta, 'Asignación Pagos'!$F:$F), 0), pagos+retenciones+pagos_manuales)) | AK11: =IF(AN11="","",AH11-AJ11) | AL11: =IF(AN11="","",IF(Q11="Sin Factura","",AI11-AJ11)) | AM11: =IF(AN11="","",IF(Q11="Sin Factura",0,P11-IFERROR(INDEX(Facturas_Odoo!$H:$H, MATCH(Q11, Facturas_Odoo!$B:$B, 0)), 0))) | AN11: =IF(AND(A11="", J11=""), "", IF(A11<>"", VALUE(MID(A11,2,LEN(A11))), AN10)) | AO11: =IF(AN11="","",IF(AD11=0,"OK",_xlfn.LET(monedaPago, IF(AA11="","USD",AA11), limitePermitido, IFERROR(VLOOKUP(monedaPago, Configuración!$A$2:$B$3, 2, FALSE), 0.15), IF(AD11>limitePermitido, "ALERTA: EXCESO (" & TEXT(limitePermitido, "0%") & " máx)", "OK")))) | AP11: =IF(AN11="","",IF(AE11=0,"OK",_xlfn.LET(fechaPago, Z11, fechaFactura, R11, diasCredito, IF(E11="Pago inmediato", 0, IFERROR(VALUE(MID(E11, 1, SEARCH(" ", E11)-1)), 0)), tolerancia, Configuración!$E$2, limiteDias, diasCredito + tolerancia, IF(OR(fechaPago="", fechaFactura=""), "REVISAR: SIN FECHA", IF(fechaPago - fechaFactura > limiteDias, "ALERTA: PAGO FUERA DE PLAZO (" & (fechaPago - fechaFactura) & " días)", "OK"))))) | AQ11: =IF(AN11="","",IF(AND(N11>0, AG11>0), IF(Configuración!$K$2="NO", "ALERTA: DESCUENTO DOBLE NO PERMITIDO", "OK"), "OK")) | AR11: =IF(AN11="","",IF(OR(AO11<>"OK", AP11<>"OK", AQ11<>"OK"), "⚠️ REVISAR", "OK"))
A12: =IF('Ordenes_Odoo'!A12="","",'Ordenes_Odoo'!A12) | B12: =IF('Ordenes_Odoo'!B12="","",'Ordenes_Odoo'!B12) | C12: =IF('Ordenes_Odoo'!C12="","",'Ordenes_Odoo'!C12) | D12: =IF('Ordenes_Odoo'!D12="","",'Ordenes_Odoo'!D12) | E12: =IF('Ordenes_Odoo'!E12="","",'Ordenes_Odoo'!E12) | F12: =IF('Ordenes_Odoo'!F12="","",'Ordenes_Odoo'!F12) | G12: =IF('Ordenes_Odoo'!G12="","",'Ordenes_Odoo'!G12) | H12: =IF('Ordenes_Odoo'!H12="","",'Ordenes_Odoo'!H12) | ... P12: =IF('Ordenes_Odoo'!P12="","",'Ordenes_Odoo'!P12) | Q12: =IF(A12="","",IFERROR(INDEX(Facturas_Odoo!$B:$B, MATCH(A12, Facturas_Odoo!$D:$D, 0)), "Sin Factura")) | R12: =IF(Q12="Sin Factura","",IFERROR(INDEX(Facturas_Odoo!$A:$A, MATCH(Q12, Facturas_Odoo!$B:$B, 0)), "")) | S12: =IF(Q12="Sin Factura","",IFERROR(_xlfn.XLOOKUP(1, (Facturas_Odoo!$D:$D=A12) * (Facturas_Odoo!$K:$K=I12), Facturas_Odoo!$L:$L, ""), "")) | T12: =IF(Q12="Sin Factura",0,IFERROR(_xlfn.XLOOKUP(1, (Facturas_Odoo!$D:$D=A12) * (Facturas_Odoo!$K:$K=I12), Facturas_Odoo!$M:$M, 0), 0)) | U12: =IF(Q12="Sin Factura",0,IFERROR(_xlfn.XLOOKUP(1, (Facturas_Odoo!$D:$D=A12) * (Facturas_Odoo!$K:$K=I12), Facturas_Odoo!$N:$N, 0), 0)) | V12: =IF(Q12="Sin Factura",0,IFERROR(_xlfn.XLOOKUP(1, (Facturas_Odoo!$D:$D=A12) * (Facturas_Odoo!$K:$K=I12), Facturas_Odoo!$O:$O, 0), 0)) | W12: =IF(Q12="Sin Factura",0,IFERROR(_xlfn.XLOOKUP(1, (Facturas_Odoo!$D:$D=A12) * (Facturas_Odoo!$K:$K=I12), Facturas_Odoo!$Q:$Q, 0), 0)) | X12: =IF(OR(Q12="Sin Factura",Q12=""),"",IFERROR(INDEX(Pagos_Odoo!$B:$B, MATCH(Q12, Pagos_Odoo!$I:$I, 0)), "Sin Pago")) | Y12: =IF(X12="Sin Pago","",IFERROR(INDEX(Pagos_Odoo!$C:$C, MATCH(X12, Pagos_Odoo!$B:$B, 0)), "")) | Z12: =IF(X12="Sin Pago","",IFERROR(INDEX(Pagos_Odoo!$A:$A, MATCH(X12, Pagos_Odoo!$B:$B, 0)), "")) | AA12: =IF(X12="Sin Pago","",IFERROR(INDEX(Pagos_Odoo!$F:$F, MATCH(X12, Pagos_Odoo!$B:$B, 0)), "")) | AB12: =IF(X12="Sin Pago",0,IFERROR(INDEX(Pagos_Odoo!$E:$E, MATCH(X12, Pagos_Odoo!$B:$B, 0)), 0)) | AC12: =IF(X12="Sin Pago","",IFERROR(INDEX(Pagos_Odoo!$G:$G, MATCH(X12, Pagos_Odoo!$B:$B, 0)), "")) | AD12: 0 | AG12: =IF(AN12="","",AD12+AE12+AF12) | AH12: =IF(AN12="","",P12*(1-AG12)) | AI12: =IF(AN12="","",IF(Q12="Sin Factura",0,IFERROR(INDEX(Facturas_Odoo!$H:$H, MATCH(Q12, Facturas_Odoo!$B:$B, 0)), 0)*(1-AG12))) | AJ12: =IF(AN12="","",_xlfn.LET(idVenta, AN12&"", pagos, IFERROR(SUMIF(Aux_Datos!$B:$B, idVenta, Aux_Datos!$L:$L), 0), retenciones, IFERROR(SUMIF(Aux_Datos!$O:$O, idVenta, Aux_Datos!$S:$S), 0), pagos_manuales, IFERROR(SUMIF('Asignación Pagos'!$G:$G, idVenta, 'Asignación Pagos'!$F:$F), 0), pagos+retenciones+pagos_manuales)) | AK12: =IF(AN12="","",AH12-AJ12) | AL12: =IF(AN12="","",IF(Q12="Sin Factura","",AI12-AJ12)) | AM12: =IF(AN12="","",IF(Q12="Sin Factura",0,P12-IFERROR(INDEX(Facturas_Odoo!$H:$H, MATCH(Q12, Facturas_Odoo!$B:$B, 0)), 0))) | AN12: =IF(AND(A12="", J12=""), "", IF(A12<>"", VALUE(MID(A12,2,LEN(A12))), AN11)) | AO12: =IF(AN12="","",IF(AD12=0,"OK",_xlfn.LET(monedaPago, IF(AA12="","USD",AA12), limitePermitido, IFERROR(VLOOKUP(monedaPago, Configuración!$A$2:$B$3, 2, FALSE), 0.15), IF(AD12>limitePermitido, "ALERTA: EXCESO (" & TEXT(limitePermitido, "0%") & " máx)", "OK")))) | AP12: =IF(AN12="","",IF(AE12=0,"OK",_xlfn.LET(fechaPago, Z12, fechaFactura, R12, diasCredito, IF(E12="Pago inmediato", 0, IFERROR(VALUE(MID(E12, 1, SEARCH(" ", E12)-1)), 0)), tolerancia, Configuración!$E$2, limiteDias, diasCredito + tolerancia, IF(OR(fechaPago="", fechaFactura=""), "REVISAR: SIN FECHA", IF(fechaPago - fechaFactura > limiteDias, "ALERTA: PAGO FUERA DE PLAZO (" & (fechaPago - fechaFactura) & " días)", "OK"))))) | AQ12: =IF(AN12="","",IF(AND(N12>0, AG12>0), IF(Configuración!$K$2="NO", "ALERTA: DESCUENTO DOBLE NO PERMITIDO", "OK"), "OK")) | AR12: =IF(AN12="","",IF(OR(AO12<>"OK", AP12<>"OK", AQ12<>"OK"), "⚠️ REVISAR", "OK"))
A13: =IF('Ordenes_Odoo'!A13="","",'Ordenes_Odoo'!A13) | B13: =IF('Ordenes_Odoo'!B13="","",'Ordenes_Odoo'!B13) | C13: =IF('Ordenes_Odoo'!C13="","",'Ordenes_Odoo'!C13) | D13: =IF('Ordenes_Odoo'!D13="","",'Ordenes_Odoo'!D13) | E13: =IF('Ordenes_Odoo'!E13="","",'Ordenes_Odoo'!E13) | F13: =IF('Ordenes_Odoo'!F13="","",'Ordenes_Odoo'!F13) | G13: =IF('Ordenes_Odoo'!G13="","",'Ordenes_Odoo'!G13) | H13: =IF('Ordenes_Odoo'!H13="","",'Ordenes_Odoo'!H13) | ... P13: =IF('Ordenes_Odoo'!P13="","",'Ordenes_Odoo'!P13) | Q13: =IF(A13="","",IFERROR(INDEX(Facturas_Odoo!$B:$B, MATCH(A13, Facturas_Odoo!$D:$D, 0)), "Sin Factura")) | R13: =IF(Q13="Sin Factura","",IFERROR(INDEX(Facturas_Odoo!$A:$A, MATCH(Q13, Facturas_Odoo!$B:$B, 0)), "")) | S13: =IF(Q13="Sin Factura","",IFERROR(_xlfn.XLOOKUP(1, (Facturas_Odoo!$D:$D=A13) * (Facturas_Odoo!$K:$K=I13), Facturas_Odoo!$L:$L, ""), "")) | T13: =IF(Q13="Sin Factura",0,IFERROR(_xlfn.XLOOKUP(1, (Facturas_Odoo!$D:$D=A13) * (Facturas_Odoo!$K:$K=I13), Facturas_Odoo!$M:$M, 0), 0)) | U13: =IF(Q13="Sin Factura",0,IFERROR(_xlfn.XLOOKUP(1, (Facturas_Odoo!$D:$D=A13) * (Facturas_Odoo!$K:$K=I13), Facturas_Odoo!$N:$N, 0), 0)) | V13: =IF(Q13="Sin Factura",0,IFERROR(_xlfn.XLOOKUP(1, (Facturas_Odoo!$D:$D=A13) * (Facturas_Odoo!$K:$K=I13), Facturas_Odoo!$O:$O, 0), 0)) | W13: =IF(Q13="Sin Factura",0,IFERROR(_xlfn.XLOOKUP(1, (Facturas_Odoo!$D:$D=A13) * (Facturas_Odoo!$K:$K=I13), Facturas_Odoo!$Q:$Q, 0), 0)) | X13: =IF(OR(Q13="Sin Factura",Q13=""),"",IFERROR(INDEX(Pagos_Odoo!$B:$B, MATCH(Q13, Pagos_Odoo!$I:$I, 0)), "Sin Pago")) | Y13: =IF(X13="Sin Pago","",IFERROR(INDEX(Pagos_Odoo!$C:$C, MATCH(X13, Pagos_Odoo!$B:$B, 0)), "")) | Z13: =IF(X13="Sin Pago","",IFERROR(INDEX(Pagos_Odoo!$A:$A, MATCH(X13, Pagos_Odoo!$B:$B, 0)), "")) | AA13: =IF(X13="Sin Pago","",IFERROR(INDEX(Pagos_Odoo!$F:$F, MATCH(X13, Pagos_Odoo!$B:$B, 0)), "")) | AB13: =IF(X13="Sin Pago",0,IFERROR(INDEX(Pagos_Odoo!$E:$E, MATCH(X13, Pagos_Odoo!$B:$B, 0)), 0)) | AC13: =IF(X13="Sin Pago","",IFERROR(INDEX(Pagos_Odoo!$G:$G, MATCH(X13, Pagos_Odoo!$B:$B, 0)), "")) | AD13: 0 | AG13: =IF(AN13="","",AD13+AE13+AF13) | AH13: =IF(AN13="","",P13*(1-AG13)) | AI13: =IF(AN13="","",IF(Q13="Sin Factura",0,IFERROR(INDEX(Facturas_Odoo!$H:$H, MATCH(Q13, Facturas_Odoo!$B:$B, 0)), 0)*(1-AG13))) | AJ13: =IF(AN13="","",_xlfn.LET(idVenta, AN13&"", pagos, IFERROR(SUMIF(Aux_Datos!$B:$B, idVenta, Aux_Datos!$L:$L), 0), retenciones, IFERROR(SUMIF(Aux_Datos!$O:$O, idVenta, Aux_Datos!$S:$S), 0), pagos_manuales, IFERROR(SUMIF('Asignación Pagos'!$G:$G, idVenta, 'Asignación Pagos'!$F:$F), 0), pagos+retenciones+pagos_manuales)) | AK13: =IF(AN13="","",AH13-AJ13) | AL13: =IF(AN13="","",IF(Q13="Sin Factura","",AI13-AJ13)) | AM13: =IF(AN13="","",IF(Q13="Sin Factura",0,P13-IFERROR(INDEX(Facturas_Odoo!$H:$H, MATCH(Q13, Facturas_Odoo!$B:$B, 0)), 0))) | AN13: =IF(AND(A13="", J13=""), "", IF(A13<>"", VALUE(MID(A13,2,LEN(A13))), AN12)) | AO13: =IF(AN13="","",IF(AD13=0,"OK",_xlfn.LET(monedaPago, IF(AA13="","USD",AA13), limitePermitido, IFERROR(VLOOKUP(monedaPago, Configuración!$A$2:$B$3, 2, FALSE), 0.15), IF(AD13>limitePermitido, "ALERTA: EXCESO (" & TEXT(limitePermitido, "0%") & " máx)", "OK")))) | AP13: =IF(AN13="","",IF(AE13=0,"OK",_xlfn.LET(fechaPago, Z13, fechaFactura, R13, diasCredito, IF(E13="Pago inmediato", 0, IFERROR(VALUE(MID(E13, 1, SEARCH(" ", E13)-1)), 0)), tolerancia, Configuración!$E$2, limiteDias, diasCredito + tolerancia, IF(OR(fechaPago="", fechaFactura=""), "REVISAR: SIN FECHA", IF(fechaPago - fechaFactura > limiteDias, "ALERTA: PAGO FUERA DE PLAZO (" & (fechaPago - fechaFactura) & " días)", "OK"))))) | AQ13: =IF(AN13="","",IF(AND(N13>0, AG13>0), IF(Configuración!$K$2="NO", "ALERTA: DESCUENTO DOBLE NO PERMITIDO", "OK"), "OK")) | AR13: =IF(AN13="","",IF(OR(AO13<>"OK", AP13<>"OK", AQ13<>"OK"), "⚠️ REVISAR", "OK"))
A14: =IF('Ordenes_Odoo'!A14="","",'Ordenes_Odoo'!A14) | B14: =IF('Ordenes_Odoo'!B14="","",'Ordenes_Odoo'!B14) | C14: =IF('Ordenes_Odoo'!C14="","",'Ordenes_Odoo'!C14) | D14: =IF('Ordenes_Odoo'!D14="","",'Ordenes_Odoo'!D14) | E14: =IF('Ordenes_Odoo'!E14="","",'Ordenes_Odoo'!E14) | F14: =IF('Ordenes_Odoo'!F14="","",'Ordenes_Odoo'!F14) | G14: =IF('Ordenes_Odoo'!G14="","",'Ordenes_Odoo'!G14) | H14: =IF('Ordenes_Odoo'!H14="","",'Ordenes_Odoo'!H14) | ... P14: =IF('Ordenes_Odoo'!P14="","",'Ordenes_Odoo'!P14) | Q14: =IF(A14="","",IFERROR(INDEX(Facturas_Odoo!$B:$B, MATCH(A14, Facturas_Odoo!$D:$D, 0)), "Sin Factura")) | R14: =IF(Q14="Sin Factura","",IFERROR(INDEX(Facturas_Odoo!$A:$A, MATCH(Q14, Facturas_Odoo!$B:$B, 0)), "")) | S14: =IF(Q14="Sin Factura","",IFERROR(_xlfn.XLOOKUP(1, (Facturas_Odoo!$D:$D=A14) * (Facturas_Odoo!$K:$K=I14), Facturas_Odoo!$L:$L, ""), "")) | T14: =IF(Q14="Sin Factura",0,IFERROR(_xlfn.XLOOKUP(1, (Facturas_Odoo!$D:$D=A14) * (Facturas_Odoo!$K:$K=I14), Facturas_Odoo!$M:$M, 0), 0)) | U14: =IF(Q14="Sin Factura",0,IFERROR(_xlfn.XLOOKUP(1, (Facturas_Odoo!$D:$D=A14) * (Facturas_Odoo!$K:$K=I14), Facturas_Odoo!$N:$N, 0), 0)) | V14: =IF(Q14="Sin Factura",0,IFERROR(_xlfn.XLOOKUP(1, (Facturas_Odoo!$D:$D=A14) * (Facturas_Odoo!$K:$K=I14), Facturas_Odoo!$O:$O, 0), 0)) | W14: =IF(Q14="Sin Factura",0,IFERROR(_xlfn.XLOOKUP(1, (Facturas_Odoo!$D:$D=A14) * (Facturas_Odoo!$K:$K=I14), Facturas_Odoo!$Q:$Q, 0), 0)) | X14: =IF(OR(Q14="Sin Factura",Q14=""),"",IFERROR(INDEX(Pagos_Odoo!$B:$B, MATCH(Q14, Pagos_Odoo!$I:$I, 0)), "Sin Pago")) | Y14: =IF(X14="Sin Pago","",IFERROR(INDEX(Pagos_Odoo!$C:$C, MATCH(X14, Pagos_Odoo!$B:$B, 0)), "")) | Z14: =IF(X14="Sin Pago","",IFERROR(INDEX(Pagos_Odoo!$A:$A, MATCH(X14, Pagos_Odoo!$B:$B, 0)), "")) | AA14: =IF(X14="Sin Pago","",IFERROR(INDEX(Pagos_Odoo!$F:$F, MATCH(X14, Pagos_Odoo!$B:$B, 0)), "")) | AB14: =IF(X14="Sin Pago",0,IFERROR(INDEX(Pagos_Odoo!$E:$E, MATCH(X14, Pagos_Odoo!$B:$B, 0)), 0)) | AC14: =IF(X14="Sin Pago","",IFERROR(INDEX(Pagos_Odoo!$G:$G, MATCH(X14, Pagos_Odoo!$B:$B, 0)), "")) | AD14: 0 | AG14: =IF(AN14="","",AD14+AE14+AF14) | AH14: =IF(AN14="","",P14*(1-AG14)) | AI14: =IF(AN14="","",IF(Q14="Sin Factura",0,IFERROR(INDEX(Facturas_Odoo!$H:$H, MATCH(Q14, Facturas_Odoo!$B:$B, 0)), 0)*(1-AG14))) | AJ14: =IF(AN14="","",_xlfn.LET(idVenta, AN14&"", pagos, IFERROR(SUMIF(Aux_Datos!$B:$B, idVenta, Aux_Datos!$L:$L), 0), retenciones, IFERROR(SUMIF(Aux_Datos!$O:$O, idVenta, Aux_Datos!$S:$S), 0), pagos_manuales, IFERROR(SUMIF('Asignación Pagos'!$G:$G, idVenta, 'Asignación Pagos'!$F:$F), 0), pagos+retenciones+pagos_manuales)) | AK14: =IF(AN14="","",AH14-AJ14) | AL14: =IF(AN14="","",IF(Q14="Sin Factura","",AI14-AJ14)) | AM14: =IF(AN14="","",IF(Q14="Sin Factura",0,P14-IFERROR(INDEX(Facturas_Odoo!$H:$H, MATCH(Q14, Facturas_Odoo!$B:$B, 0)), 0))) | AN14: =IF(AND(A14="", J14=""), "", IF(A14<>"", VALUE(MID(A14,2,LEN(A14))), AN13)) | AO14: =IF(AN14="","",IF(AD14=0,"OK",_xlfn.LET(monedaPago, IF(AA14="","USD",AA14), limitePermitido, IFERROR(VLOOKUP(monedaPago, Configuración!$A$2:$B$3, 2, FALSE), 0.15), IF(AD14>limitePermitido, "ALERTA: EXCESO (" & TEXT(limitePermitido, "0%") & " máx)", "OK")))) | AP14: =IF(AN14="","",IF(AE14=0,"OK",_xlfn.LET(fechaPago, Z14, fechaFactura, R14, diasCredito, IF(E14="Pago inmediato", 0, IFERROR(VALUE(MID(E14, 1, SEARCH(" ", E14)-1)), 0)), tolerancia, Configuración!$E$2, limiteDias, diasCredito + tolerancia, IF(OR(fechaPago="", fechaFactura=""), "REVISAR: SIN FECHA", IF(fechaPago - fechaFactura > limiteDias, "ALERTA: PAGO FUERA DE PLAZO (" & (fechaPago - fechaFactura) & " días)", "OK"))))) | AQ14: =IF(AN14="","",IF(AND(N14>0, AG14>0), IF(Configuración!$K$2="NO", "ALERTA: DESCUENTO DOBLE NO PERMITIDO", "OK"), "OK")) | AR14: =IF(AN14="","",IF(OR(AO14<>"OK", AP14<>"OK", AQ14<>"OK"), "⚠️ REVISAR", "OK"))
... A389: =IF('Ordenes_Odoo'!A389="","",'Ordenes_Odoo'!A389) | B389: =IF('Ordenes_Odoo'!B389="","",'Ordenes_Odoo'!B389) | C389: =IF('Ordenes_Odoo'!C389="","",'Ordenes_Odoo'!C389) | D389: =IF('Ordenes_Odoo'!D389="","",'Ordenes_Odoo'!D389) | E389: =IF('Ordenes_Odoo'!E389="","",'Ordenes_Odoo'!E389) | F389: =IF('Ordenes_Odoo'!F389="","",'Ordenes_Odoo'!F389) | G389: =IF('Ordenes_Odoo'!G389="","",'Ordenes_Odoo'!G389) | H389: =IF('Ordenes_Odoo'!H389="","",'Ordenes_Odoo'!H389) | ... P389: =IF('Ordenes_Odoo'!P389="","",'Ordenes_Odoo'!P389) | Q389: =IF(A389="","",IFERROR(INDEX(Facturas_Odoo!$B:$B, MATCH(A389, Facturas_Odoo!$D:$D, 0)), "Sin Factura")) | R389: =IF(Q389="Sin Factura","",IFERROR(INDEX(Facturas_Odoo!$A:$A, MATCH(Q389, Facturas_Odoo!$B:$B, 0)), "")) | S389: =IF(Q389="Sin Factura","",IFERROR(_xlfn.XLOOKUP(1, (Facturas_Odoo!$D:$D=A389) * (Facturas_Odoo!$K:$K=I389), Facturas_Odoo!$L:$L, ""), "")) | T389: =IF(Q389="Sin Factura",0,IFERROR(_xlfn.XLOOKUP(1, (Facturas_Odoo!$D:$D=A389) * (Facturas_Odoo!$K:$K=I389), Facturas_Odoo!$M:$M, 0), 0)) | U389: =IF(Q389="Sin Factura",0,IFERROR(_xlfn.XLOOKUP(1, (Facturas_Odoo!$D:$D=A389) * (Facturas_Odoo!$K:$K=I389), Facturas_Odoo!$N:$N, 0), 0)) | V389: =IF(Q389="Sin Factura",0,IFERROR(_xlfn.XLOOKUP(1, (Facturas_Odoo!$D:$D=A389) * (Facturas_Odoo!$K:$K=I389), Facturas_Odoo!$O:$O, 0), 0)) | W389: =IF(Q389="Sin Factura",0,IFERROR(_xlfn.XLOOKUP(1, (Facturas_Odoo!$D:$D=A389) * (Facturas_Odoo!$K:$K=I389), Facturas_Odoo!$Q:$Q, 0), 0)) | X389: =IF(OR(Q389="Sin Factura",Q389=""),"",IFERROR(INDEX(Pagos_Odoo!$B:$B, MATCH(Q389, Pagos_Odoo!$I:$I, 0)), "Sin Pago")) | Y389: =IF(X389="Sin Pago","",IFERROR(INDEX(Pagos_Odoo!$C:$C, MATCH(X389, Pagos_Odoo!$B:$B, 0)), "")) | Z389: =IF(X389="Sin Pago","",IFERROR(INDEX(Pagos_Odoo!$A:$A, MATCH(X389, Pagos_Odoo!$B:$B, 0)), "")) | AA389: =IF(X389="Sin Pago","",IFERROR(INDEX(Pagos_Odoo!$F:$F, MATCH(X389, Pagos_Odoo!$B:$B, 0)), "")) | AB389: =IF(X389="Sin Pago",0,IFERROR(INDEX(Pagos_Odoo!$E:$E, MATCH(X389, Pagos_Odoo!$B:$B, 0)), 0)) | AC389: =IF(X389="Sin Pago","",IFERROR(INDEX(Pagos_Odoo!$G:$G, MATCH(X389, Pagos_Odoo!$B:$B, 0)), "")) | AD389: 0 | AG389: =IF(AN389="","",AD389+AE389+AF389) | AH389: =IF(AN389="","",P389*(1-AG389)) | AI389: =IF(AN389="","",IF(Q389="Sin Factura",0,IFERROR(INDEX(Facturas_Odoo!$H:$H, MATCH(Q389, Facturas_Odoo!$B:$B, 0)), 0)*(1-AG389))) | AJ389: =IF(AN389="","",_xlfn.LET(idVenta, AN389&"", pagos, IFERROR(SUMIF(Aux_Datos!$B:$B, idVenta, Aux_Datos!$L:$L), 0), retenciones, IFERROR(SUMIF(Aux_Datos!$O:$O, idVenta, Aux_Datos!$S:$S), 0), pagos_manuales, IFERROR(SUMIF('Asignación Pagos'!$G:$G, idVenta, 'Asignación Pagos'!$F:$F), 0), pagos+retenciones+pagos_manuales)) | AK389: =IF(AN389="","",AH389-AJ389) | AL389: =IF(AN389="","",IF(Q389="Sin Factura","",AI389-AJ389)) | AM389: =IF(AN389="","",IF(Q389="Sin Factura",0,P389-IFERROR(INDEX(Facturas_Odoo!$H:$H, MATCH(Q389, Facturas_Odoo!$B:$B, 0)), 0))) | AN389: =IF(AND(A389="", J389=""), "", IF(A389<>"", VALUE(MID(A389,2,LEN(A389))), AN388)) | AO389: =IF(AN389="","",IF(AD389=0,"OK",_xlfn.LET(monedaPago, IF(AA389="","USD",AA389), limitePermitido, IFERROR(VLOOKUP(monedaPago, Configuración!$A$2:$B$3, 2, FALSE), 0.15), IF(AD389>limitePermitido, "ALERTA: EXCESO (" & TEXT(limitePermitido, "0%") & " máx)", "OK")))) | AP389: =IF(AN389="","",IF(AE389=0,"OK",_xlfn.LET(fechaPago, Z389, fechaFactura, R389, diasCredito, IF(E389="Pago inmediato", 0, IFERROR(VALUE(MID(E389, 1, SEARCH(" ", E389)-1)), 0)), tolerancia, Configuración!$E$2, limiteDias, diasCredito + tolerancia, IF(OR(fechaPago="", fechaFactura=""), "REVISAR: SIN FECHA", IF(fechaPago - fechaFactura > limiteDias, "ALERTA: PAGO FUERA DE PLAZO (" & (fechaPago - fechaFactura) & " días)", "OK"))))) | AQ389: =IF(AN389="","",IF(AND(N389>0, AG389>0), IF(Configuración!$K$2="NO", "ALERTA: DESCUENTO DOBLE NO PERMITIDO", "OK"), "OK")) | AR389: =IF(AN389="","",IF(OR(AO389<>"OK", AP389<>"OK", AQ389<>"OK"), "⚠️ REVISAR", "OK"))
A390: =IF('Ordenes_Odoo'!A390="","",'Ordenes_Odoo'!A390) | B390: =IF('Ordenes_Odoo'!B390="","",'Ordenes_Odoo'!B390) | C390: =IF('Ordenes_Odoo'!C390="","",'Ordenes_Odoo'!C390) | D390: =IF('Ordenes_Odoo'!D390="","",'Ordenes_Odoo'!D390) | E390: =IF('Ordenes_Odoo'!E390="","",'Ordenes_Odoo'!E390) | F390: =IF('Ordenes_Odoo'!F390="","",'Ordenes_Odoo'!F390) | G390: =IF('Ordenes_Odoo'!G390="","",'Ordenes_Odoo'!G390) | H390: =IF('Ordenes_Odoo'!H390="","",'Ordenes_Odoo'!H390) | ... P390: =IF('Ordenes_Odoo'!P390="","",'Ordenes_Odoo'!P390) | Q390: =IF(A390="","",IFERROR(INDEX(Facturas_Odoo!$B:$B, MATCH(A390, Facturas_Odoo!$D:$D, 0)), "Sin Factura")) | R390: =IF(Q390="Sin Factura","",IFERROR(INDEX(Facturas_Odoo!$A:$A, MATCH(Q390, Facturas_Odoo!$B:$B, 0)), "")) | S390: =IF(Q390="Sin Factura","",IFERROR(_xlfn.XLOOKUP(1, (Facturas_Odoo!$D:$D=A390) * (Facturas_Odoo!$K:$K=I390), Facturas_Odoo!$L:$L, ""), "")) | T390: =IF(Q390="Sin Factura",0,IFERROR(_xlfn.XLOOKUP(1, (Facturas_Odoo!$D:$D=A390) * (Facturas_Odoo!$K:$K=I390), Facturas_Odoo!$M:$M, 0), 0)) | U390: =IF(Q390="Sin Factura",0,IFERROR(_xlfn.XLOOKUP(1, (Facturas_Odoo!$D:$D=A390) * (Facturas_Odoo!$K:$K=I390), Facturas_Odoo!$N:$N, 0), 0)) | V390: =IF(Q390="Sin Factura",0,IFERROR(_xlfn.XLOOKUP(1, (Facturas_Odoo!$D:$D=A390) * (Facturas_Odoo!$K:$K=I390), Facturas_Odoo!$O:$O, 0), 0)) | W390: =IF(Q390="Sin Factura",0,IFERROR(_xlfn.XLOOKUP(1, (Facturas_Odoo!$D:$D=A390) * (Facturas_Odoo!$K:$K=I390), Facturas_Odoo!$Q:$Q, 0), 0)) | X390: =IF(OR(Q390="Sin Factura",Q390=""),"",IFERROR(INDEX(Pagos_Odoo!$B:$B, MATCH(Q390, Pagos_Odoo!$I:$I, 0)), "Sin Pago")) | Y390: =IF(X390="Sin Pago","",IFERROR(INDEX(Pagos_Odoo!$C:$C, MATCH(X390, Pagos_Odoo!$B:$B, 0)), "")) | Z390: =IF(X390="Sin Pago","",IFERROR(INDEX(Pagos_Odoo!$A:$A, MATCH(X390, Pagos_Odoo!$B:$B, 0)), "")) | AA390: =IF(X390="Sin Pago","",IFERROR(INDEX(Pagos_Odoo!$F:$F, MATCH(X390, Pagos_Odoo!$B:$B, 0)), "")) | AB390: =IF(X390="Sin Pago",0,IFERROR(INDEX(Pagos_Odoo!$E:$E, MATCH(X390, Pagos_Odoo!$B:$B, 0)), 0)) | AC390: =IF(X390="Sin Pago","",IFERROR(INDEX(Pagos_Odoo!$G:$G, MATCH(X390, Pagos_Odoo!$B:$B, 0)), "")) | AD390: 0 | AE390: 0.0509 | AG390: =IF(AN390="","",AD390+AE390+AF390) | AH390: =IF(AN390="","",P390*(1-AG390)) | AI390: =IF(AN390="","",IF(Q390="Sin Factura",0,IFERROR(INDEX(Facturas_Odoo!$H:$H, MATCH(Q390, Facturas_Odoo!$B:$B, 0)), 0)*(1-AG390))) | AJ390: =IF(AN390="","",_xlfn.LET(idVenta, AN390&"", pagos, IFERROR(SUMIF(Aux_Datos!$B:$B, idVenta, Aux_Datos!$L:$L), 0), retenciones, IFERROR(SUMIF(Aux_Datos!$O:$O, idVenta, Aux_Datos!$S:$S), 0), pagos_manuales, IFERROR(SUMIF('Asignación Pagos'!$G:$G, idVenta, 'Asignación Pagos'!$F:$F), 0), pagos+retenciones+pagos_manuales)) | AK390: =IF(AN390="","",AH390-AJ390) | AL390: =IF(AN390="","",IF(Q390="Sin Factura","",AI390-AJ390)) | AM390: =IF(AN390="","",IF(Q390="Sin Factura",0,P390-IFERROR(INDEX(Facturas_Odoo!$H:$H, MATCH(Q390, Facturas_Odoo!$B:$B, 0)), 0))) | AN390: =IF(AND(A390="", J390=""), "", IF(A390<>"", VALUE(MID(A390,2,LEN(A390))), AN389)) | AO390: =IF(AN390="","",IF(AD390=0,"OK",_xlfn.LET(monedaPago, IF(AA390="","USD",AA390), limitePermitido, IFERROR(VLOOKUP(monedaPago, Configuración!$A$2:$B$3, 2, FALSE), 0.15), IF(AD390>limitePermitido, "ALERTA: EXCESO (" & TEXT(limitePermitido, "0%") & " máx)", "OK")))) | AP390: =IF(AN390="","",IF(AE390=0,"OK",_xlfn.LET(fechaPago, Z390, fechaFactura, R390, diasCredito, IF(E390="Pago inmediato", 0, IFERROR(VALUE(MID(E390, 1, SEARCH(" ", E390)-1)), 0)), tolerancia, Configuración!$E$2, limiteDias, diasCredito + tolerancia, IF(OR(fechaPago="", fechaFactura=""), "REVISAR: SIN FECHA", IF(fechaPago - fechaFactura > limiteDias, "ALERTA: PAGO FUERA DE PLAZO (" & (fechaPago - fechaFactura) & " días)", "OK"))))) | AQ390: =IF(AN390="","",IF(AND(N390>0, AG390>0), IF(Configuración!$K$2="NO", "ALERTA: DESCUENTO DOBLE NO PERMITIDO", "OK"), "OK")) | AR390: =IF(AN390="","",IF(OR(AO390<>"OK", AP390<>"OK", AQ390<>"OK"), "⚠️ REVISAR", "OK"))
