Workbook
Name Limite_descuento: #REF!

Sheet Antiguedad

Sheet Cuentas x Cobrar

Sheet Cuentas x Cobrar x Mes

Sheet Cuentas x Dias Vencimiento

Sheet Cuentas x Vendedor

Sheet Resumen Ventas x Mes

Sheet Ventas
A1: Referencia de la orden | B1: Fecha de la orden | C1: Cliente | D1: Vendedor | E1: Total | F1: Terminos de pago | G1: Descuento x Diferencial % | H1: Dcto Pronto Pago % | I1: Numero de Orden | J1: Fecha | K1: Dias de credito | L1: Vencimiento | M1: Total C/Dcto | N1: Dias Vencido | O1: Estado Vencimiento | P1: Monto Pagado USD | Q1: Moneda de pago | R1: Saldo Orden | S1: Ultimo Pago | T1: Status de Pago | U1: Prioridad de Cobro | V1: Dias desde el ultimo Pago | W1: Validacion Descuento Diferencial | X1: Validacion Descuento Pronto Pago | Y1: Cobrado | Z1: Validación por Diferencial | AA1: Columna 27 | AB1: Columna 28 | AC1: Columna 29 | AD1: Columna 30 | AE1: Columna 31 | AF1: Columna 32
A2: S00004 | B2: 46090.24 | C2: GARAJE Y TALLERES FRIDELBA, C.A | D2: VILLABONA CORREA ALBA ESTEFANIA | E2: 232.98 | F2: Pago inmediato | G2: =IF($E2=0,0,IF(SUMIF(Aux_Datos!$B:$B,$I2,Aux_Datos!$K:$K)/$E2>=VLOOKUP(IF(COUNTIFS(Aux_Datos!$B:$B,$I2,Aux_Datos!$D:$D,"<>USD")=0,"USD","VES"),'Limites de Descuento'!$A$2:$D$4,4,FALSE),MAX(0,1-SUMIF(Aux_Datos!$B:$B,$I2,Aux_Datos!$K:$K)/$E2),0)) -> 0.24886256 | I2: =VALUE(MID(A2,2,LEN(A2))) -> 4 | J2: =INT(B2) -> 46090 | K2: =IF(F2="Pago inmediato", 0, IF(F2="", "", IFERROR(VALUE(MID(F2, 1, SEARCH(" ", F2)-1)), ""))) -> 0 | L2: =J2+K2+1 -> 46091 | M2: =E2-(E2*G2)-(E2*H2) -> 175 | N2: =IF(T2="PAGADA", 0, IF(L2 < TODAY(), TODAY() - L2, 0)) -> 0 | O2: =IF(T2="PAGADA", "PAGADA", IF(L2 < TODAY(), "VENCIDA", "EN TIEMPO")) -> PAGADA | P2: =LET( idVenta, I2&"", montoTotal, M2, pagos, IFERROR(SUMIF(Aux_Datos!$B:$B, idVenta, Aux_Datos!$K:$K), 0), retenciones, IFERROR(SUMIF(Aux_Datos!$N:$N, idVenta, Aux_Datos!$R:$R), 0), pagos + retenciones ) -> 175 | Q2: =IF(P2=0, "Sin Pago", LET( idVenta, I2&"", montoTotalPagado, P2, pagoUSD, IFERROR(SUMIFS(Aux_Datos!$C:$C, Aux_Datos!$B:$B, idVenta, Aux_Datos!$D:$D, "USD"), 0), pagoVES, IFERROR(SUMIFS(Aux_Datos!$C:$C, Aux_Datos!$B:$B, idVenta, Aux_Datos!$D:$D, "VES"), 0), IF(pagoUSD >= (montoTotalPagado * 0.84), "USD", IF(pagoVES >= (montoTotalPagado * 0.84), "VES", "MIXTO")) ) ) -> USD | R2: =M2-P2 -> 0 | S2: =IF(P2=0, "Sin Pago", IFERROR( MAXIFS(Aux_Datos!$A:$A, Aux_Datos!$B:$B, I2&""), IFERROR(MAXIFS(Aux_Datos!$A:$A, Aux_Datos!$B:$B, VALUE(I2)), "Revisar ID") ) ) -> 46100 | T2: =IF(R2<=0, "PAGADA", IF(P2>0, "PAGO PARCIAL", "PENDIENTE")) -> PAGADA | U2: =IF(AND(T2<>"PAGADA", L2<TODAY()), "CRÍTICO: VENCIDA", IF(T2="PAGADA", "SOLVENTE", "EN TIEMPO")) -> SOLVENTE | V2: =IF(T2="PAGADA", 0, IF(S2 < TODAY(), TODAY() - S2, 0)) -> 0 | W2: =IF(P2=0, "Sin Pago", LET( monedaPago, Q2, descuentoAplicado, G2, limitePermitido, IFERROR(VLOOKUP(monedaPago, 'Limites de Descuento'!$A$2:$B595, 2, FALSE), 0), IF(descuentoAplicado > limitePermitido, "ALERTA: EXCESO (" & TEXT(limitePermitido, "0%") & " máx)", "OK") ) ) -> OK | X2: =IF(OR(H2=0, S2="Sin Pago"), "", IF(AND(H2 > 0, S2 > (L2 + 2)), "⚠️ REVISAR DESCUENTO", "OK")) | Y2: {=IF(ISBLANK(I2:I595), , SUMIF(Aux_Datos!B:B, I2:I595, Aux_Datos!K:K))} -> 175 | Z2: {=IF(E2:E595="","",IF(E2:E595=0,"SIN TOTAL",IFNA(IF(P2:P595/E2:E595>=VLOOKUP(Q2:Q595,'Limites de Descuento'!$A$2:$D$4,4,FALSE),"CUMPLE","NO CUMPLE"),"SIN MONEDA VÁLIDA")))} -> CUMPLE
A3: S00007 | B3: 46079.461 | C3: EMPRENDIMIENTO IRMA RODRIGUEZ 6 | D3: CALDERON TERAN ARGIMIRO ANTONIO | E3: 246 | F3: Pago inmediato | G3: =IF($E3=0,0,IF(SUMIF(Aux_Datos!$B:$B,$I3,Aux_Datos!$K:$K)/$E3>=VLOOKUP(IF(COUNTIFS(Aux_Datos!$B:$B,$I3,Aux_Datos!$D:$D,"<>USD")=0,"USD","VES"),'Limites de Descuento'!$A$2:$D$4,4,FALSE),MAX(0,1-SUMIF(Aux_Datos!$B:$B,$I3,Aux_Datos!$K:$K)/$E3),0)) -> 0 | I3: =VALUE(MID(A3,2,LEN(A3))) -> 7 | J3: =INT(B3) -> 46079 | K3: =IF(F3="Pago inmediato", 0, IF(F3="", "", IFERROR(VALUE(MID(F3, 1, SEARCH(" ", F3)-1)), ""))) -> 0 | L3: =J3+K3+1 -> 46080 | M3: =E3-(E3*G3)-(E3*H3) -> 246 | N3: =IF(T3="PAGADA", 0, IF(L3 < TODAY(), TODAY() - L3, 0)) -> 0 | O3: =IF(T3="PAGADA", "PAGADA", IF(L3 < TODAY(), "VENCIDA", "EN TIEMPO")) -> PAGADA | P3: =LET( idVenta, I3&"", montoTotal, M3, pagos, IFERROR(SUMIF(Aux_Datos!$B:$B, idVenta, Aux_Datos!$K:$K), 0), retenciones, IFERROR(SUMIF(Aux_Datos!$N:$N, idVenta, Aux_Datos!$R:$R), 0), pagos + retenciones ) -> 246 | Q3: =IF(P3=0, "Sin Pago", LET( idVenta, I3&"", montoTotalPagado, P3, pagoUSD, IFERROR(SUMIFS(Aux_Datos!$C:$C, Aux_Datos!$B:$B, idVenta, Aux_Datos!$D:$D, "USD"), 0), pagoVES, IFERROR(SUMIFS(Aux_Datos!$C:$C, Aux_Datos!$B:$B, idVenta, Aux_Datos!$D:$D, "VES"), 0), IF(pagoUSD >= (montoTotalPagado * 0.84), "USD", IF(pagoVES >= (montoTotalPagado * 0.84), "VES", "MIXTO")) ) ) -> USD | R3: =M3-P3 -> 0 | S3: =IF(P3=0, "Sin Pago", IFERROR( MAXIFS(Aux_Datos!$A:$A, Aux_Datos!$B:$B, I3&""), IFERROR(MAXIFS(Aux_Datos!$A:$A, Aux_Datos!$B:$B, VALUE(I3)), "Revisar ID") ) ) -> 46084 | T3: =IF(R3<=0, "PAGADA", IF(P3>0, "PAGO PARCIAL", "PENDIENTE")) -> PAGADA | U3: =IF(AND(T3<>"PAGADA", L3<TODAY()), "CRÍTICO: VENCIDA", IF(T3="PAGADA", "SOLVENTE", "EN TIEMPO")) -> SOLVENTE | V3: =IF(T3="PAGADA", 0, IF(S3 < TODAY(), TODAY() - S3, 0)) -> 0 | W3: =IF(P3=0, "Sin Pago", LET( monedaPago, Q3, descuentoAplicado, G3, limitePermitido, IFERROR(VLOOKUP(monedaPago, 'Limites de Descuento'!$A$2:$B595, 2, FALSE), 0), IF(descuentoAplicado > limitePermitido, "ALERTA: EXCESO (" & TEXT(limitePermitido, "0%") & " máx)", "OK") ) ) -> OK | X3: =IF(OR(H3=0, S3="Sin Pago"), "", IF(AND(H3 > 0, S3 > (L3 + 2)), "⚠️ REVISAR DESCUENTO", "OK")) | Y3: 246 | Z3: CUMPLE
A4: S00008 | B4: 46079.503 | C4: ZIP MARKET, CA | D4: CALDERON TERAN ARGIMIRO ANTONIO | E4: 35.33 | F4: Pago inmediato | G4: =IF($E4=0,0,IF(SUMIF(Aux_Datos!$B:$B,$I4,Aux_Datos!$K:$K)/$E4>=VLOOKUP(IF(COUNTIFS(Aux_Datos!$B:$B,$I4,Aux_Datos!$D:$D,"<>USD")=0,"USD","VES"),'Limites de Descuento'!$A$2:$D$4,4,FALSE),MAX(0,1-SUMIF(Aux_Datos!$B:$B,$I4,Aux_Datos!$K:$K)/$E4),0)) -> 0 | I4: =VALUE(MID(A4,2,LEN(A4))) -> 8 | J4: =INT(B4) -> 46079 | K4: =IF(F4="Pago inmediato", 0, IF(F4="", "", IFERROR(VALUE(MID(F4, 1, SEARCH(" ", F4)-1)), ""))) -> 0 | L4: =J4+K4+1 -> 46080 | M4: =E4-(E4*G4)-(E4*H4) -> 35.33 | N4: =IF(T4="PAGADA", 0, IF(L4 < TODAY(), TODAY() - L4, 0)) -> 0 | O4: =IF(T4="PAGADA", "PAGADA", IF(L4 < TODAY(), "VENCIDA", "EN TIEMPO")) -> PAGADA | P4: =LET( idVenta, I4&"", montoTotal, M4, pagos, IFERROR(SUMIF(Aux_Datos!$B:$B, idVenta, Aux_Datos!$K:$K), 0), retenciones, IFERROR(SUMIF(Aux_Datos!$N:$N, idVenta, Aux_Datos!$R:$R), 0), pagos + retenciones ) -> 85.33 | Q4: =IF(P4=0, "Sin Pago", LET( idVenta, I4&"", montoTotalPagado, P4, pagoUSD, IFERROR(SUMIFS(Aux_Datos!$C:$C, Aux_Datos!$B:$B, idVenta, Aux_Datos!$D:$D, "USD"), 0), pagoVES, IFERROR(SUMIFS(Aux_Datos!$C:$C, Aux_Datos!$B:$B, idVenta, Aux_Datos!$D:$D, "VES"), 0), IF(pagoUSD >= (montoTotalPagado * 0.84), "USD", IF(pagoVES >= (montoTotalPagado * 0.84), "VES", "MIXTO")) ) ) -> USD | R4: =M4-P4 -> -50 | S4: =IF(P4=0, "Sin Pago", IFERROR( MAXIFS(Aux_Datos!$A:$A, Aux_Datos!$B:$B, I4&""), IFERROR(MAXIFS(Aux_Datos!$A:$A, Aux_Datos!$B:$B, VALUE(I4)), "Revisar ID") ) ) -> 46174 | T4: =IF(R4<=0, "PAGADA", IF(P4>0, "PAGO PARCIAL", "PENDIENTE")) -> PAGADA | U4: =IF(AND(T4<>"PAGADA", L4<TODAY()), "CRÍTICO: VENCIDA", IF(T4="PAGADA", "SOLVENTE", "EN TIEMPO")) -> SOLVENTE | V4: =IF(T4="PAGADA", 0, IF(S4 < TODAY(), TODAY() - S4, 0)) -> 0 | W4: =IF(P4=0, "Sin Pago", LET( monedaPago, Q4, descuentoAplicado, G4, limitePermitido, IFERROR(VLOOKUP(monedaPago, 'Limites de Descuento'!$A$2:$B595, 2, FALSE), 0), IF(descuentoAplicado > limitePermitido, "ALERTA: EXCESO (" & TEXT(limitePermitido, "0%") & " máx)", "OK") ) ) -> OK | X4: =IF(OR(H4=0, S4="Sin Pago"), "", IF(AND(H4 > 0, S4 > (L4 + 2)), "⚠️ REVISAR DESCUENTO", "OK")) | Y4: 85.33 | Z4: CUMPLE
A5: S00009 | B5: 46079.509 | C5: E&M CAR SHOP C.A | D5: CALDERON TERAN ARGIMIRO ANTONIO | E5: 335.98 | F5: Pago inmediato | G5: =IF($E5=0,0,IF(SUMIF(Aux_Datos!$B:$B,$I5,Aux_Datos!$K:$K)/$E5>=VLOOKUP(IF(COUNTIFS(Aux_Datos!$B:$B,$I5,Aux_Datos!$D:$D,"<>USD")=0,"USD","VES"),'Limites de Descuento'!$A$2:$D$4,4,FALSE),MAX(0,1-SUMIF(Aux_Datos!$B:$B,$I5,Aux_Datos!$K:$K)/$E5),0)) -> 0 | I5: =VALUE(MID(A5,2,LEN(A5))) -> 9 | J5: =INT(B5) -> 46079 | K5: =IF(F5="Pago inmediato", 0, IF(F5="", "", IFERROR(VALUE(MID(F5, 1, SEARCH(" ", F5)-1)), ""))) -> 0 | L5: =J5+K5+1 -> 46080 | M5: =E5-(E5*G5)-(E5*H5) -> 335.98 | N5: =IF(T5="PAGADA", 0, IF(L5 < TODAY(), TODAY() - L5, 0)) -> 0 | O5: =IF(T5="PAGADA", "PAGADA", IF(L5 < TODAY(), "VENCIDA", "EN TIEMPO")) -> PAGADA | P5: =LET( idVenta, I5&"", montoTotal, M5, pagos, IFERROR(SUMIF(Aux_Datos!$B:$B, idVenta, Aux_Datos!$K:$K), 0), retenciones, IFERROR(SUMIF(Aux_Datos!$N:$N, idVenta, Aux_Datos!$R:$R), 0), pagos + retenciones ) -> 396.47318 | Q5: =IF(P5=0, "Sin Pago", LET( idVenta, I5&"", montoTotalPagado, P5, pagoUSD, IFERROR(SUMIFS(Aux_Datos!$C:$C, Aux_Datos!$B:$B, idVenta, Aux_Datos!$D:$D, "USD"), 0), pagoVES, IFERROR(SUMIFS(Aux_Datos!$C:$C, Aux_Datos!$B:$B, idVenta, Aux_Datos!$D:$D, "VES"), 0), IF(pagoUSD >= (montoTotalPagado * 0.84), "USD", IF(pagoVES >= (montoTotalPagado * 0.84), "VES", "MIXTO")) ) ) -> VES | R5: =M5-P5 -> -60.493179 | S5: =IF(P5=0, "Sin Pago", IFERROR( MAXIFS(Aux_Datos!$A:$A, Aux_Datos!$B:$B, I5&""), IFERROR(MAXIFS(Aux_Datos!$A:$A, Aux_Datos!$B:$B, VALUE(I5)), "Revisar ID") ) ) -> 46083 | T5: =IF(R5<=0, "PAGADA", IF(P5>0, "PAGO PARCIAL", "PENDIENTE")) -> PAGADA | U5: =IF(AND(T5<>"PAGADA", L5<TODAY()), "CRÍTICO: VENCIDA", IF(T5="PAGADA", "SOLVENTE", "EN TIEMPO")) -> SOLVENTE | V5: =IF(T5="PAGADA", 0, IF(S5 < TODAY(), TODAY() - S5, 0)) -> 0 | W5: =IF(P5=0, "Sin Pago", LET( monedaPago, Q5, descuentoAplicado, G5, limitePermitido, IFERROR(VLOOKUP(monedaPago, 'Limites de Descuento'!$A$2:$B595, 2, FALSE), 0), IF(descuentoAplicado > limitePermitido, "ALERTA: EXCESO (" & TEXT(limitePermitido, "0%") & " máx)", "OK") ) ) -> OK | X5: =IF(OR(H5=0, S5="Sin Pago"), "", IF(AND(H5 > 0, S5 > (L5 + 2)), "⚠️ REVISAR DESCUENTO", "OK")) | Y5: 396.47318 | Z5: CUMPLE
A6: S00010 | B6: 46097.354 | C6: TERA INGENIERIA Y SERVICIOS INDUSTRIALES, C.A | D6: Marco Romero | E6: 27781.08 | F6: 21 días | G6: =IF($E6=0,0,IF(SUMIF(Aux_Datos!$B:$B,$I6,Aux_Datos!$K:$K)/$E6>=VLOOKUP(IF(COUNTIFS(Aux_Datos!$B:$B,$I6,Aux_Datos!$D:$D,"<>USD")=0,"USD","VES"),'Limites de Descuento'!$A$2:$D$4,4,FALSE),MAX(0,1-SUMIF(Aux_Datos!$B:$B,$I6,Aux_Datos!$K:$K)/$E6),0)) -> 0 | I6: =VALUE(MID(A6,2,LEN(A6))) -> 10 | J6: =INT(B6) -> 46097 | K6: =IF(F6="Pago inmediato", 0, IF(F6="", "", IFERROR(VALUE(MID(F6, 1, SEARCH(" ", F6)-1)), ""))) -> 21 | L6: =J6+K6+1 -> 46119 | M6: =E6-(E6*G6)-(E6*H6) -> 27781.08 | N6: =IF(T6="PAGADA", 0, IF(L6 < TODAY(), TODAY() - L6, 0)) -> 0 | O6: =IF(T6="PAGADA", "PAGADA", IF(L6 < TODAY(), "VENCIDA", "EN TIEMPO")) -> PAGADA | P6: =LET( idVenta, I6&"", montoTotal, M6, pagos, IFERROR(SUMIF(Aux_Datos!$B:$B, idVenta, Aux_Datos!$K:$K), 0), retenciones, IFERROR(SUMIF(Aux_Datos!$N:$N, idVenta, Aux_Datos!$R:$R), 0), pagos + retenciones ) -> 27781.08 | Q6: =IF(P6=0, "Sin Pago", LET( idVenta, I6&"", montoTotalPagado, P6, pagoUSD, IFERROR(SUMIFS(Aux_Datos!$C:$C, Aux_Datos!$B:$B, idVenta, Aux_Datos!$D:$D, "USD"), 0), pagoVES, IFERROR(SUMIFS(Aux_Datos!$C:$C, Aux_Datos!$B:$B, idVenta, Aux_Datos!$D:$D, "VES"), 0), IF(pagoUSD >= (montoTotalPagado * 0.84), "USD", IF(pagoVES >= (montoTotalPagado * 0.84), "VES", "MIXTO")) ) ) -> USD | R6: =M6-P6 -> 0 | S6: =IF(P6=0, "Sin Pago", IFERROR( MAXIFS(Aux_Datos!$A:$A, Aux_Datos!$B:$B, I6&""), IFERROR(MAXIFS(Aux_Datos!$A:$A, Aux_Datos!$B:$B, VALUE(I6)), "Revisar ID") ) ) -> 46181 | T6: =IF(R6<=0, "PAGADA", IF(P6>0, "PAGO PARCIAL", "PENDIENTE")) -> PAGADA | U6: =IF(AND(T6<>"PAGADA", L6<TODAY()), "CRÍTICO: VENCIDA", IF(T6="PAGADA", "SOLVENTE", "EN TIEMPO")) -> SOLVENTE | V6: =IF(T6="PAGADA", 0, IF(S6 < TODAY(), TODAY() - S6, 0)) -> 0 | W6: =IF(P6=0, "Sin Pago", LET( monedaPago, Q6, descuentoAplicado, G6, limitePermitido, IFERROR(VLOOKUP(monedaPago, 'Limites de Descuento'!$A$2:$B595, 2, FALSE), 0), IF(descuentoAplicado > limitePermitido, "ALERTA: EXCESO (" & TEXT(limitePermitido, "0%") & " máx)", "OK") ) ) -> OK | X6: =IF(OR(H6=0, S6="Sin Pago"), "", IF(AND(H6 > 0, S6 > (L6 + 2)), "⚠️ REVISAR DESCUENTO", "OK")) | Y6: 27781.08 | Z6: CUMPLE
A7: S00011 | B7: 46094.725 | C7: MOTO MARCE 21, CA | D7: CALDERON TERAN ARGIMIRO ANTONIO | E7: 63.77 | F7: Pago inmediato | G7: =IF($E7=0,0,IF(SUMIF(Aux_Datos!$B:$B,$I7,Aux_Datos!$K:$K)/$E7>=VLOOKUP(IF(COUNTIFS(Aux_Datos!$B:$B,$I7,Aux_Datos!$D:$D,"<>USD")=0,"USD","VES"),'Limites de Descuento'!$A$2:$D$4,4,FALSE),MAX(0,1-SUMIF(Aux_Datos!$B:$B,$I7,Aux_Datos!$K:$K)/$E7),0)) -> 0 | I7: =VALUE(MID(A7,2,LEN(A7))) -> 11 | J7: =INT(B7) -> 46094 | K7: =IF(F7="Pago inmediato", 0, IF(F7="", "", IFERROR(VALUE(MID(F7, 1, SEARCH(" ", F7)-1)), ""))) -> 0 | L7: =J7+K7+1 -> 46095 | M7: =E7-(E7*G7)-(E7*H7) -> 63.77 | N7: =IF(T7="PAGADA", 0, IF(L7 < TODAY(), TODAY() - L7, 0)) -> 0 | O7: =IF(T7="PAGADA", "PAGADA", IF(L7 < TODAY(), "VENCIDA", "EN TIEMPO")) -> PAGADA | P7: =LET( idVenta, I7&"", montoTotal, M7, pagos, IFERROR(SUMIF(Aux_Datos!$B:$B, idVenta, Aux_Datos!$K:$K), 0), retenciones, IFERROR(SUMIF(Aux_Datos!$N:$N, idVenta, Aux_Datos!$R:$R), 0), pagos + retenciones ) -> 74.960088 | Q7: =IF(P7=0, "Sin Pago", LET( idVenta, I7&"", montoTotalPagado, P7, pagoUSD, IFERROR(SUMIFS(Aux_Datos!$C:$C, Aux_Datos!$B:$B, idVenta, Aux_Datos!$D:$D, "USD"), 0), pagoVES, IFERROR(SUMIFS(Aux_Datos!$C:$C, Aux_Datos!$B:$B, idVenta, Aux_Datos!$D:$D, "VES"), 0), IF(pagoUSD >= (montoTotalPagado * 0.84), "USD", IF(pagoVES >= (montoTotalPagado * 0.84), "VES", "MIXTO")) ) ) -> VES | R7: =M7-P7 -> -11.190088 | S7: =IF(P7=0, "Sin Pago", IFERROR( MAXIFS(Aux_Datos!$A:$A, Aux_Datos!$B:$B, I7&""), IFERROR(MAXIFS(Aux_Datos!$A:$A, Aux_Datos!$B:$B, VALUE(I7)), "Revisar ID") ) ) -> 46171 | T7: =IF(R7<=0, "PAGADA", IF(P7>0, "PAGO PARCIAL", "PENDIENTE")) -> PAGADA | U7: =IF(AND(T7<>"PAGADA", L7<TODAY()), "CRÍTICO: VENCIDA", IF(T7="PAGADA", "SOLVENTE", "EN TIEMPO")) -> SOLVENTE | V7: =IF(T7="PAGADA", 0, IF(S7 < TODAY(), TODAY() - S7, 0)) -> 0 | W7: =IF(P7=0, "Sin Pago", LET( monedaPago, Q7, descuentoAplicado, G7, limitePermitido, IFERROR(VLOOKUP(monedaPago, 'Limites de Descuento'!$A$2:$B595, 2, FALSE), 0), IF(descuentoAplicado > limitePermitido, "ALERTA: EXCESO (" & TEXT(limitePermitido, "0%") & " máx)", "OK") ) ) -> OK | X7: =IF(OR(H7=0, S7="Sin Pago"), "", IF(AND(H7 > 0, S7 > (L7 + 2)), "⚠️ REVISAR DESCUENTO", "OK")) | Y7: 74.960088 | Z7: CUMPLE
A8: S00014 | B8: 46090.241 | C8: SPEED RACING, CA | D8: OCANTO ZABALA ROSALVY DEL CARMEN | E8: 82.24 | F8: 7 días | G8: =IF($E8=0,0,IF(SUMIF(Aux_Datos!$B:$B,$I8,Aux_Datos!$K:$K)/$E8>=VLOOKUP(IF(COUNTIFS(Aux_Datos!$B:$B,$I8,Aux_Datos!$D:$D,"<>USD")=0,"USD","VES"),'Limites de Descuento'!$A$2:$D$4,4,FALSE),MAX(0,1-SUMIF(Aux_Datos!$B:$B,$I8,Aux_Datos!$K:$K)/$E8),0)) -> 0 | I8: =VALUE(MID(A8,2,LEN(A8))) -> 14 | J8: =INT(B8) -> 46090 | K8: =IF(F8="Pago inmediato", 0, IF(F8="", "", IFERROR(VALUE(MID(F8, 1, SEARCH(" ", F8)-1)), ""))) -> 7 | L8: =J8+K8+1 -> 46098 | M8: =E8-(E8*G8)-(E8*H8) -> 82.24 | N8: =IF(T8="PAGADA", 0, IF(L8 < TODAY(), TODAY() - L8, 0)) -> 0 | O8: =IF(T8="PAGADA", "PAGADA", IF(L8 < TODAY(), "VENCIDA", "EN TIEMPO")) -> PAGADA | P8: =LET( idVenta, I8&"", montoTotal, M8, pagos, IFERROR(SUMIF(Aux_Datos!$B:$B, idVenta, Aux_Datos!$K:$K), 0), retenciones, IFERROR(SUMIF(Aux_Datos!$N:$N, idVenta, Aux_Datos!$R:$R), 0), pagos + retenciones ) -> 86.578275 | Q8: =IF(P8=0, "Sin Pago", LET( idVenta, I8&"", montoTotalPagado, P8, pagoUSD, IFERROR(SUMIFS(Aux_Datos!$C:$C, Aux_Datos!$B:$B, idVenta, Aux_Datos!$D:$D, "USD"), 0), pagoVES, IFERROR(SUMIFS(Aux_Datos!$C:$C, Aux_Datos!$B:$B, idVenta, Aux_Datos!$D:$D, "VES"), 0), IF(pagoUSD >= (montoTotalPagado * 0.84), "USD", IF(pagoVES >= (montoTotalPagado * 0.84), "VES", "MIXTO")) ) ) -> VES | R8: =M8-P8 -> -4.3382748 | S8: =IF(P8=0, "Sin Pago", IFERROR( MAXIFS(Aux_Datos!$A:$A, Aux_Datos!$B:$B, I8&""), IFERROR(MAXIFS(Aux_Datos!$A:$A, Aux_Datos!$B:$B, VALUE(I8)), "Revisar ID") ) ) -> 46156 | T8: =IF(R8<=0, "PAGADA", IF(P8>0, "PAGO PARCIAL", "PENDIENTE")) -> PAGADA | U8: =IF(AND(T8<>"PAGADA", L8<TODAY()), "CRÍTICO: VENCIDA", IF(T8="PAGADA", "SOLVENTE", "EN TIEMPO")) -> SOLVENTE | V8: =IF(T8="PAGADA", 0, IF(S8 < TODAY(), TODAY() - S8, 0)) -> 0 | W8: =IF(P8=0, "Sin Pago", LET( monedaPago, Q8, descuentoAplicado, G8, limitePermitido, IFERROR(VLOOKUP(monedaPago, 'Limites de Descuento'!$A$2:$B595, 2, FALSE), 0), IF(descuentoAplicado > limitePermitido, "ALERTA: EXCESO (" & TEXT(limitePermitido, "0%") & " máx)", "OK") ) ) -> OK | X8: =IF(OR(H8=0, S8="Sin Pago"), "", IF(AND(H8 > 0, S8 > (L8 + 2)), "⚠️ REVISAR DESCUENTO", "OK")) | Y8: 86.578275 | Z8: CUMPLE
A9: S00015 | B9: 46090.241 | C9: SERVICIOS Y MANTENIMIENTO SPACARS, C.A, Henry Blanco | D9: TORO ARDILES DAVID JOSE | E9: 954.79 | F9: 7 días | G9: =IF($E9=0,0,IF(SUMIF(Aux_Datos!$B:$B,$I9,Aux_Datos!$K:$K)/$E9>=VLOOKUP(IF(COUNTIFS(Aux_Datos!$B:$B,$I9,Aux_Datos!$D:$D,"<>USD")=0,"USD","VES"),'Limites de Descuento'!$A$2:$D$4,4,FALSE),MAX(0,1-SUMIF(Aux_Datos!$B:$B,$I9,Aux_Datos!$K:$K)/$E9),0)) -> 0 | I9: =VALUE(MID(A9,2,LEN(A9))) -> 15 | J9: =INT(B9) -> 46090 | K9: =IF(F9="Pago inmediato", 0, IF(F9="", "", IFERROR(VALUE(MID(F9, 1, SEARCH(" ", F9)-1)), ""))) -> 7 | L9: =J9+K9+1 -> 46098 | M9: =E9-(E9*G9)-(E9*H9) -> 954.79 | N9: =IF(T9="PAGADA", 0, IF(L9 < TODAY(), TODAY() - L9, 0)) -> 102 | O9: =IF(T9="PAGADA", "PAGADA", IF(L9 < TODAY(), "VENCIDA", "EN TIEMPO")) -> VENCIDA | P9: =LET( idVenta, I9&"", montoTotal, M9, pagos, IFERROR(SUMIF(Aux_Datos!$B:$B, idVenta, Aux_Datos!$K:$K), 0), retenciones, IFERROR(SUMIF(Aux_Datos!$N:$N, idVenta, Aux_Datos!$R:$R), 0), pagos + retenciones ) -> 713.0517 | Q9: =IF(P9=0, "Sin Pago", LET( idVenta, I9&"", montoTotalPagado, P9, pagoUSD, IFERROR(SUMIFS(Aux_Datos!$C:$C, Aux_Datos!$B:$B, idVenta, Aux_Datos!$D:$D, "USD"), 0), pagoVES, IFERROR(SUMIFS(Aux_Datos!$C:$C, Aux_Datos!$B:$B, idVenta, Aux_Datos!$D:$D, "VES"), 0), IF(pagoUSD >= (montoTotalPagado * 0.84), "USD", IF(pagoVES >= (montoTotalPagado * 0.84), "VES", "MIXTO")) ) ) -> VES | R9: =M9-P9 -> 241.7383 | S9: =IF(P9=0, "Sin Pago", IFERROR( MAXIFS(Aux_Datos!$A:$A, Aux_Datos!$B:$B, I9&""), IFERROR(MAXIFS(Aux_Datos!$A:$A, Aux_Datos!$B:$B, VALUE(I9)), "Revisar ID") ) ) -> 46129 | T9: =IF(R9<=0, "PAGADA", IF(P9>0, "PAGO PARCIAL", "PENDIENTE")) -> PAGO PARCIAL | U9: =IF(AND(T9<>"PAGADA", L9<TODAY()), "CRÍTICO: VENCIDA", IF(T9="PAGADA", "SOLVENTE", "EN TIEMPO")) -> CRÍTICO: VENCIDA | V9: =IF(T9="PAGADA", 0, IF(S9 < TODAY(), TODAY() - S9, 0)) -> 71 | W9: =IF(P9=0, "Sin Pago", LET( monedaPago, Q9, descuentoAplicado, G9, limitePermitido, IFERROR(VLOOKUP(monedaPago, 'Limites de Descuento'!$A$2:$B595, 2, FALSE), 0), IF(descuentoAplicado > limitePermitido, "ALERTA: EXCESO (" & TEXT(limitePermitido, "0%") & " máx)", "OK") ) ) -> OK | X9: =IF(OR(H9=0, S9="Sin Pago"), "", IF(AND(H9 > 0, S9 > (L9 + 2)), "⚠️ REVISAR DESCUENTO", "OK")) | Y9: 713.0517 | Z9: NO CUMPLE
A10: S00017 | B10: 46090.242 | C10: MOTO REPUESTOS LA FLECHA, C.A. | D10: TORO ARDILES DAVID JOSE | E10: 104.36 | F10: 7 días | G10: =IF($E10=0,0,IF(SUMIF(Aux_Datos!$B:$B,$I10,Aux_Datos!$K:$K)/$E10>=VLOOKUP(IF(COUNTIFS(Aux_Datos!$B:$B,$I10,Aux_Datos!$D:$D,"<>USD")=0,"USD","VES"),'Limites de Descuento'!$A$2:$D$4,4,FALSE),MAX(0,1-SUMIF(Aux_Datos!$B:$B,$I10,Aux_Datos!$K:$K)/$E10),0)) -> 0 | I10: =VALUE(MID(A10,2,LEN(A10))) -> 17 | J10: =INT(B10) -> 46090 | K10: =IF(F10="Pago inmediato", 0, IF(F10="", "", IFERROR(VALUE(MID(F10, 1, SEARCH(" ", F10)-1)), ""))) -> 7 | L10: =J10+K10+1 -> 46098 | M10: =E10-(E10*G10)-(E10*H10) -> 104.36 | N10: =IF(T10="PAGADA", 0, IF(L10 < TODAY(), TODAY() - L10, 0)) -> 0 | O10: =IF(T10="PAGADA", "PAGADA", IF(L10 < TODAY(), "VENCIDA", "EN TIEMPO")) -> PAGADA | P10: 1847 | Q10: =IF(P10=0, "Sin Pago", LET( idVenta, I10&"", montoTotalPagado, P10, pagoUSD, IFERROR(SUMIFS(Aux_Datos!$C:$C, Aux_Datos!$B:$B, idVenta, Aux_Datos!$D:$D, "USD"), 0), pagoVES, IFERROR(SUMIFS(Aux_Datos!$C:$C, Aux_Datos!$B:$B, idVenta, Aux_Datos!$D:$D, "VES"), 0), IF(pagoUSD >= (montoTotalPagado * 0.84), "USD", IF(pagoVES >= (montoTotalPagado * 0.84), "VES", "MIXTO")) ) ) -> VES | R10: 0 | S10: =IF(P10=0, "Sin Pago", IFERROR( MAXIFS(Aux_Datos!$A:$A, Aux_Datos!$B:$B, I10&""), IFERROR(MAXIFS(Aux_Datos!$A:$A, Aux_Datos!$B:$B, VALUE(I10)), "Revisar ID") ) ) -> 46133 | T10: =IF(R10<=0, "PAGADA", IF(P10>0, "PAGO PARCIAL", "PENDIENTE")) -> PAGADA | U10: =IF(AND(T10<>"PAGADA", L10<TODAY()), "CRÍTICO: VENCIDA", IF(T10="PAGADA", "SOLVENTE", "EN TIEMPO")) -> SOLVENTE | V10: =IF(T10="PAGADA", 0, IF(S10 < TODAY(), TODAY() - S10, 0)) -> 0 | W10: =IF(P10=0, "Sin Pago", LET( monedaPago, Q10, descuentoAplicado, G10, limitePermitido, IFERROR(VLOOKUP(monedaPago, 'Limites de Descuento'!$A$2:$B595, 2, FALSE), 0), IF(descuentoAplicado > limitePermitido, "ALERTA: EXCESO (" & TEXT(limitePermitido, "0%") & " máx)", "OK") ) ) -> OK | X10: =IF(OR(H10=0, S10="Sin Pago"), "", IF(AND(H10 > 0, S10 > (L10 + 2)), "⚠️ REVISAR DESCUENTO", "OK")) | Y10: 116.81781 | Z10: CUMPLE
A11: S00018 | B11: 46090.242 | C11: AUTO ACCESORIOS VZLA, C.A. | D11: VILLABONA CORREA ALBA ESTEFANIA | E11: 96 | F11: 7 días | G11: =IF($E11=0,0,IF(SUMIF(Aux_Datos!$B:$B,$I11,Aux_Datos!$K:$K)/$E11>=VLOOKUP(IF(COUNTIFS(Aux_Datos!$B:$B,$I11,Aux_Datos!$D:$D,"<>USD")=0,"USD","VES"),'Limites de Descuento'!$A$2:$D$4,4,FALSE),MAX(0,1-SUMIF(Aux_Datos!$B:$B,$I11,Aux_Datos!$K:$K)/$E11),0)) -> 0 | I11: =VALUE(MID(A11,2,LEN(A11))) -> 18 | J11: =INT(B11) -> 46090 | K11: =IF(F11="Pago inmediato", 0, IF(F11="", "", IFERROR(VALUE(MID(F11, 1, SEARCH(" ", F11)-1)), ""))) -> 7 | L11: =J11+K11+1 -> 46098 | M11: =E11-(E11*G11)-(E11*H11) -> 96 | N11: =IF(T11="PAGADA", 0, IF(L11 < TODAY(), TODAY() - L11, 0)) -> 0 | O11: =IF(T11="PAGADA", "PAGADA", IF(L11 < TODAY(), "VENCIDA", "EN TIEMPO")) -> PAGADA | P11: =LET( idVenta, I11&"", montoTotal, M11, pagos, IFERROR(SUMIF(Aux_Datos!$B:$B, idVenta, Aux_Datos!$K:$K), 0), retenciones, IFERROR(SUMIF(Aux_Datos!$N:$N, idVenta, Aux_Datos!$R:$R), 0), pagos + retenciones ) -> 96 | Q11: =IF(P11=0, "Sin Pago", LET( idVenta, I11&"", montoTotalPagado, P11, pagoUSD, IFERROR(SUMIFS(Aux_Datos!$C:$C, Aux_Datos!$B:$B, idVenta, Aux_Datos!$D:$D, "USD"), 0), pagoVES, IFERROR(SUMIFS(Aux_Datos!$C:$C, Aux_Datos!$B:$B, idVenta, Aux_Datos!$D:$D, "VES"), 0), IF(pagoUSD >= (montoTotalPagado * 0.84), "USD", IF(pagoVES >= (montoTotalPagado * 0.84), "VES", "MIXTO")) ) ) -> USD | R11: =M11-P11 -> 0 | S11: =IF(P11=0, "Sin Pago", IFERROR( MAXIFS(Aux_Datos!$A:$A, Aux_Datos!$B:$B, I11&""), IFERROR(MAXIFS(Aux_Datos!$A:$A, Aux_Datos!$B:$B, VALUE(I11)), "Revisar ID") ) ) -> 46126 | T11: =IF(R11<=0, "PAGADA", IF(P11>0, "PAGO PARCIAL", "PENDIENTE")) -> PAGADA | U11: =IF(AND(T11<>"PAGADA", L11<TODAY()), "CRÍTICO: VENCIDA", IF(T11="PAGADA", "SOLVENTE", "EN TIEMPO")) -> SOLVENTE | V11: =IF(T11="PAGADA", 0, IF(S11 < TODAY(), TODAY() - S11, 0)) -> 0 | W11: =IF(P11=0, "Sin Pago", LET( monedaPago, Q11, descuentoAplicado, G11, limitePermitido, IFERROR(VLOOKUP(monedaPago, 'Limites de Descuento'!$A$2:$B595, 2, FALSE), 0), IF(descuentoAplicado > limitePermitido, "ALERTA: EXCESO (" & TEXT(limitePermitido, "0%") & " máx)", "OK") ) ) -> OK | X11: =IF(OR(H11=0, S11="Sin Pago"), "", IF(AND(H11 > 0, S11 > (L11 + 2)), "⚠️ REVISAR DESCUENTO", "OK")) | Y11: 96 | Z11: CUMPLE
A12: S00019 | B12: 46084.647 | C12: Ruta 8 Autopartes,c.a. | D12: OCANTO ZABALA ROSALVY DEL CARMEN | E12: 78.25 | F12: 7 días | G12: =IF($E12=0,0,IF(SUMIF(Aux_Datos!$B:$B,$I12,Aux_Datos!$K:$K)/$E12>=VLOOKUP(IF(COUNTIFS(Aux_Datos!$B:$B,$I12,Aux_Datos!$D:$D,"<>USD")=0,"USD","VES"),'Limites de Descuento'!$A$2:$D$4,4,FALSE),MAX(0,1-SUMIF(Aux_Datos!$B:$B,$I12,Aux_Datos!$K:$K)/$E12),0)) -> 0 | I12: =VALUE(MID(A12,2,LEN(A12))) -> 19 | J12: =INT(B12) -> 46084 | K12: =IF(F12="Pago inmediato", 0, IF(F12="", "", IFERROR(VALUE(MID(F12, 1, SEARCH(" ", F12)-1)), ""))) -> 7 | L12: =J12+K12+1 -> 46092 | M12: =E12-(E12*G12)-(E12*H12) -> 78.25 | N12: =IF(T12="PAGADA", 0, IF(L12 < TODAY(), TODAY() - L12, 0)) -> 0 | O12: =IF(T12="PAGADA", "PAGADA", IF(L12 < TODAY(), "VENCIDA", "EN TIEMPO")) -> PAGADA | P12: =LET( idVenta, I12&"", montoTotal, M12, pagos, IFERROR(SUMIF(Aux_Datos!$B:$B, idVenta, Aux_Datos!$K:$K), 0), retenciones, IFERROR(SUMIF(Aux_Datos!$N:$N, idVenta, Aux_Datos!$R:$R), 0), pagos + retenciones ) -> 91.89855 | Q12: =IF(P12=0, "Sin Pago", LET( idVenta, I12&"", montoTotalPagado, P12, pagoUSD, IFERROR(SUMIFS(Aux_Datos!$C:$C, Aux_Datos!$B:$B, idVenta, Aux_Datos!$D:$D, "USD"), 0), pagoVES, IFERROR(SUMIFS(Aux_Datos!$C:$C, Aux_Datos!$B:$B, idVenta, Aux_Datos!$D:$D, "VES"), 0), IF(pagoUSD >= (montoTotalPagado * 0.84), "USD", IF(pagoVES >= (montoTotalPagado * 0.84), "VES", "MIXTO")) ) ) -> VES | R12: =M12-P12 -> -13.64855 | S12: =IF(P12=0, "Sin Pago", IFERROR( MAXIFS(Aux_Datos!$A:$A, Aux_Datos!$B:$B, I12&""), IFERROR(MAXIFS(Aux_Datos!$A:$A, Aux_Datos!$B:$B, VALUE(I12)), "Revisar ID") ) ) -> 46140 | T12: =IF(R12<=0, "PAGADA", IF(P12>0, "PAGO PARCIAL", "PENDIENTE")) -> PAGADA | U12: =IF(AND(T12<>"PAGADA", L12<TODAY()), "CRÍTICO: VENCIDA", IF(T12="PAGADA", "SOLVENTE", "EN TIEMPO")) -> SOLVENTE | V12: =IF(T12="PAGADA", 0, IF(S12 < TODAY(), TODAY() - S12, 0)) -> 0 | W12: =IF(P12=0, "Sin Pago", LET( monedaPago, Q12, descuentoAplicado, G12, limitePermitido, IFERROR(VLOOKUP(monedaPago, 'Limites de Descuento'!$A$2:$B595, 2, FALSE), 0), IF(descuentoAplicado > limitePermitido, "ALERTA: EXCESO (" & TEXT(limitePermitido, "0%") & " máx)", "OK") ) ) -> OK | X12: =IF(OR(H12=0, S12="Sin Pago"), "", IF(AND(H12 > 0, S12 > (L12 + 2)), "⚠️ REVISAR DESCUENTO", "OK")) | Y12: 91.89855 | Z12: CUMPLE
A13: S00020 | B13: 46090.242 | C13: EMPRENDIMIENTO TOMAS MARCANO 5 | D13: VILLABONA CORREA ALBA ESTEFANIA | E13: 472.53 | F13: 7 días | G13: =IF($E13=0,0,IF(SUMIF(Aux_Datos!$B:$B,$I13,Aux_Datos!$K:$K)/$E13>=VLOOKUP(IF(COUNTIFS(Aux_Datos!$B:$B,$I13,Aux_Datos!$D:$D,"<>USD")=0,"USD","VES"),'Limites de Descuento'!$A$2:$D$4,4,FALSE),MAX(0,1-SUMIF(Aux_Datos!$B:$B,$I13,Aux_Datos!$K:$K)/$E13),0)) -> 0 | I13: =VALUE(MID(A13,2,LEN(A13))) -> 20 | J13: =INT(B13) -> 46090 | K13: =IF(F13="Pago inmediato", 0, IF(F13="", "", IFERROR(VALUE(MID(F13, 1, SEARCH(" ", F13)-1)), ""))) -> 7 | L13: =J13+K13+1 -> 46098 | M13: =E13-(E13*G13)-(E13*H13) -> 472.53 | N13: =IF(T13="PAGADA", 0, IF(L13 < TODAY(), TODAY() - L13, 0)) -> 102 | O13: =IF(T13="PAGADA", "PAGADA", IF(L13 < TODAY(), "VENCIDA", "EN TIEMPO")) -> VENCIDA | P13: =LET( idVenta, I13&"", montoTotal, M13, pagos, IFERROR(SUMIF(Aux_Datos!$B:$B, idVenta, Aux_Datos!$K:$K), 0), retenciones, IFERROR(SUMIF(Aux_Datos!$N:$N, idVenta, Aux_Datos!$R:$R), 0), pagos + retenciones ) -> 166.24063 | Q13: =IF(P13=0, "Sin Pago", LET( idVenta, I13&"", montoTotalPagado, P13, pagoUSD, IFERROR(SUMIFS(Aux_Datos!$C:$C, Aux_Datos!$B:$B, idVenta, Aux_Datos!$D:$D, "USD"), 0), pagoVES, IFERROR(SUMIFS(Aux_Datos!$C:$C, Aux_Datos!$B:$B, idVenta, Aux_Datos!$D:$D, "VES"), 0), IF(pagoUSD >= (montoTotalPagado * 0.84), "USD", IF(pagoVES >= (montoTotalPagado * 0.84), "VES", "MIXTO")) ) ) -> VES | R13: =M13-P13 -> 306.28937 | S13: =IF(P13=0, "Sin Pago", IFERROR( MAXIFS(Aux_Datos!$A:$A, Aux_Datos!$B:$B, I13&""), IFERROR(MAXIFS(Aux_Datos!$A:$A, Aux_Datos!$B:$B, VALUE(I13)), "Revisar ID") ) ) -> 46177 | T13: =IF(R13<=0, "PAGADA", IF(P13>0, "PAGO PARCIAL", "PENDIENTE")) -> PAGO PARCIAL | U13: =IF(AND(T13<>"PAGADA", L13<TODAY()), "CRÍTICO: VENCIDA", IF(T13="PAGADA", "SOLVENTE", "EN TIEMPO")) -> CRÍTICO: VENCIDA | V13: =IF(T13="PAGADA", 0, IF(S13 < TODAY(), TODAY() - S13, 0)) -> 23 | W13: =IF(P13=0, "Sin Pago", LET( monedaPago, Q13, descuentoAplicado, G13, limitePermitido, IFERROR(VLOOKUP(monedaPago, 'Limites de Descuento'!$A$2:$B595, 2, FALSE), 0), IF(descuentoAplicado > limitePermitido, "ALERTA: EXCESO (" & TEXT(limitePermitido, "0%") & " máx)", "OK") ) ) -> OK | X13: =IF(OR(H13=0, S13="Sin Pago"), "", IF(AND(H13 > 0, S13 > (L13 + 2)), "⚠️ REVISAR DESCUENTO", "OK")) | Y13: 166.24063 | Z13: NO CUMPLE
A14: S00021 | B14: 46090.242 | C14: INVERSIONES SMALUM 21, C.A. | D14: VILLABONA CORREA ALBA ESTEFANIA | E14: 212.72 | F14: 7 días | G14: =IF($E14=0,0,IF(SUMIF(Aux_Datos!$B:$B,$I14,Aux_Datos!$K:$K)/$E14>=VLOOKUP(IF(COUNTIFS(Aux_Datos!$B:$B,$I14,Aux_Datos!$D:$D,"<>USD")=0,"USD","VES"),'Limites de Descuento'!$A$2:$D$4,4,FALSE),MAX(0,1-SUMIF(Aux_Datos!$B:$B,$I14,Aux_Datos!$K:$K)/$E14),0)) -> 0 | I14: =VALUE(MID(A14,2,LEN(A14))) -> 21 | J14: =INT(B14) -> 46090 | K14: =IF(F14="Pago inmediato", 0, IF(F14="", "", IFERROR(VALUE(MID(F14, 1, SEARCH(" ", F14)-1)), ""))) -> 7 | L14: =J14+K14+1 -> 46098 | M14: =E14-(E14*G14)-(E14*H14) -> 212.72 | N14: =IF(T14="PAGADA", 0, IF(L14 < TODAY(), TODAY() - L14, 0)) -> 0 | O14: =IF(T14="PAGADA", "PAGADA", IF(L14 < TODAY(), "VENCIDA", "EN TIEMPO")) -> PAGADA | P14: =LET( idVenta, I14&"", montoTotal, M14, pagos, IFERROR(SUMIF(Aux_Datos!$B:$B, idVenta, Aux_Datos!$K:$K), 0), retenciones, IFERROR(SUMIF(Aux_Datos!$N:$N, idVenta, Aux_Datos!$R:$R), 0), pagos + retenciones ) -> 238.6499 | Q14: =IF(P14=0, "Sin Pago", LET( idVenta, I14&"", montoTotalPagado, P14, pagoUSD, IFERROR(SUMIFS(Aux_Datos!$C:$C, Aux_Datos!$B:$B, idVenta, Aux_Datos!$D:$D, "USD"), 0), pagoVES, IFERROR(SUMIFS(Aux_Datos!$C:$C, Aux_Datos!$B:$B, idVenta, Aux_Datos!$D:$D, "VES"), 0), IF(pagoUSD >= (montoTotalPagado * 0.84), "USD", IF(pagoVES >= (montoTotalPagado * 0.84), "VES", "MIXTO")) ) ) -> VES | R14: =M14-P14 -> -25.929896 | S14: =IF(P14=0, "Sin Pago", IFERROR( MAXIFS(Aux_Datos!$A:$A, Aux_Datos!$B:$B, I14&""), IFERROR(MAXIFS(Aux_Datos!$A:$A, Aux_Datos!$B:$B, VALUE(I14)), "Revisar ID") ) ) -> 46153 | T14: =IF(R14<=0, "PAGADA", IF(P14>0, "PAGO PARCIAL", "PENDIENTE")) -> PAGADA | U14: =IF(AND(T14<>"PAGADA", L14<TODAY()), "CRÍTICO: VENCIDA", IF(T14="PAGADA", "SOLVENTE", "EN TIEMPO")) -> SOLVENTE | V14: =IF(T14="PAGADA", 0, IF(S14 < TODAY(), TODAY() - S14, 0)) -> 0 | W14: =IF(P14=0, "Sin Pago", LET( monedaPago, Q14, descuentoAplicado, G14, limitePermitido, IFERROR(VLOOKUP(monedaPago, 'Limites de Descuento'!$A$2:$B595, 2, FALSE), 0), IF(descuentoAplicado > limitePermitido, "ALERTA: EXCESO (" & TEXT(limitePermitido, "0%") & " máx)", "OK") ) ) -> OK | X14: =IF(OR(H14=0, S14="Sin Pago"), "", IF(AND(H14 > 0, S14 > (L14 + 2)), "⚠️ REVISAR DESCUENTO", "OK")) | Y14: 238.6499 | Z14: CUMPLE
A15: S00022 | B15: 46090.242 | C15: Autorepuestos las 24 horas | D15: MARTINEZ MONTES JEFFREY ENRIQUE | E15: 96 | F15: 7 días | G15: =IF($E15=0,0,IF(SUMIF(Aux_Datos!$B:$B,$I15,Aux_Datos!$K:$K)/$E15>=VLOOKUP(IF(COUNTIFS(Aux_Datos!$B:$B,$I15,Aux_Datos!$D:$D,"<>USD")=0,"USD","VES"),'Limites de Descuento'!$A$2:$D$4,4,FALSE),MAX(0,1-SUMIF(Aux_Datos!$B:$B,$I15,Aux_Datos!$K:$K)/$E15),0)) -> 0 | I15: =VALUE(MID(A15,2,LEN(A15))) -> 22 | J15: =INT(B15) -> 46090 | K15: =IF(F15="Pago inmediato", 0, IF(F15="", "", IFERROR(VALUE(MID(F15, 1, SEARCH(" ", F15)-1)), ""))) -> 7 | L15: =J15+K15+1 -> 46098 | M15: =E15-(E15*G15)-(E15*H15) -> 96 | N15: =IF(T15="PAGADA", 0, IF(L15 < TODAY(), TODAY() - L15, 0)) -> 0 | O15: =IF(T15="PAGADA", "PAGADA", IF(L15 < TODAY(), "VENCIDA", "EN TIEMPO")) -> PAGADA | P15: =LET( idVenta, I15&"", montoTotal, M15, pagos, IFERROR(SUMIF(Aux_Datos!$B:$B, idVenta, Aux_Datos!$K:$K), 0), retenciones, IFERROR(SUMIF(Aux_Datos!$N:$N, idVenta, Aux_Datos!$R:$R), 0), pagos + retenciones ) -> 96 | Q15: =IF(P15=0, "Sin Pago", LET( idVenta, I15&"", montoTotalPagado, P15, pagoUSD, IFERROR(SUMIFS(Aux_Datos!$C:$C, Aux_Datos!$B:$B, idVenta, Aux_Datos!$D:$D, "USD"), 0), pagoVES, IFERROR(SUMIFS(Aux_Datos!$C:$C, Aux_Datos!$B:$B, idVenta, Aux_Datos!$D:$D, "VES"), 0), IF(pagoUSD >= (montoTotalPagado * 0.84), "USD", IF(pagoVES >= (montoTotalPagado * 0.84), "VES", "MIXTO")) ) ) -> USD | R15: =M15-P15 -> 0 | S15: =IF(P15=0, "Sin Pago", IFERROR( MAXIFS(Aux_Datos!$A:$A, Aux_Datos!$B:$B, I15&""), IFERROR(MAXIFS(Aux_Datos!$A:$A, Aux_Datos!$B:$B, VALUE(I15)), "Revisar ID") ) ) -> 46111 | T15: =IF(R15<=0, "PAGADA", IF(P15>0, "PAGO PARCIAL", "PENDIENTE")) -> PAGADA | U15: =IF(AND(T15<>"PAGADA", L15<TODAY()), "CRÍTICO: VENCIDA", IF(T15="PAGADA", "SOLVENTE", "EN TIEMPO")) -> SOLVENTE | V15: =IF(T15="PAGADA", 0, IF(S15 < TODAY(), TODAY() - S15, 0)) -> 0 | W15: =IF(P15=0, "Sin Pago", LET( monedaPago, Q15, descuentoAplicado, G15, limitePermitido, IFERROR(VLOOKUP(monedaPago, 'Limites de Descuento'!$A$2:$B595, 2, FALSE), 0), IF(descuentoAplicado > limitePermitido, "ALERTA: EXCESO (" & TEXT(limitePermitido, "0%") & " máx)", "OK") ) ) -> OK | X15: =IF(OR(H15=0, S15="Sin Pago"), "", IF(AND(H15 > 0, S15 > (L15 + 2)), "⚠️ REVISAR DESCUENTO", "OK")) | Y15: 96 | Z15: CUMPLE
A16: S00023 | B16: 46090.243 | C16: Multiservicios Sanahuja 36 C.A | D16: GRIMAN DIAZ HECTOR EDUARDO | E16: 96 | F16: 15 días | G16: =IF($E16=0,0,IF(SUMIF(Aux_Datos!$B:$B,$I16,Aux_Datos!$K:$K)/$E16>=VLOOKUP(IF(COUNTIFS(Aux_Datos!$B:$B,$I16,Aux_Datos!$D:$D,"<>USD")=0,"USD","VES"),'Limites de Descuento'!$A$2:$D$4,4,FALSE),MAX(0,1-SUMIF(Aux_Datos!$B:$B,$I16,Aux_Datos!$K:$K)/$E16),0)) -> 0 | I16: =VALUE(MID(A16,2,LEN(A16))) -> 23 | J16: =INT(B16) -> 46090 | K16: =IF(F16="Pago inmediato", 0, IF(F16="", "", IFERROR(VALUE(MID(F16, 1, SEARCH(" ", F16)-1)), ""))) -> 15 | L16: =J16+K16+1 -> 46106 | M16: =E16-(E16*G16)-(E16*H16) -> 96 | N16: =IF(T16="PAGADA", 0, IF(L16 < TODAY(), TODAY() - L16, 0)) -> 0 | O16: =IF(T16="PAGADA", "PAGADA", IF(L16 < TODAY(), "VENCIDA", "EN TIEMPO")) -> PAGADA | P16: =LET( idVenta, I16&"", montoTotal, M16, pagos, IFERROR(SUMIF(Aux_Datos!$B:$B, idVenta, Aux_Datos!$K:$K), 0), retenciones, IFERROR(SUMIF(Aux_Datos!$N:$N, idVenta, Aux_Datos!$R:$R), 0), pagos + retenciones ) -> 96 | Q16: =IF(P16=0, "Sin Pago", LET( idVenta, I16&"", montoTotalPagado, P16, pagoUSD, IFERROR(SUMIFS(Aux_Datos!$C:$C, Aux_Datos!$B:$B, idVenta, Aux_Datos!$D:$D, "USD"), 0), pagoVES, IFERROR(SUMIFS(Aux_Datos!$C:$C, Aux_Datos!$B:$B, idVenta, Aux_Datos!$D:$D, "VES"), 0), IF(pagoUSD >= (montoTotalPagado * 0.84), "USD", IF(pagoVES >= (montoTotalPagado * 0.84), "VES", "MIXTO")) ) ) -> USD | R16: =M16-P16 -> 0 | S16: =IF(P16=0, "Sin Pago", IFERROR( MAXIFS(Aux_Datos!$A:$A, Aux_Datos!$B:$B, I16&""), IFERROR(MAXIFS(Aux_Datos!$A:$A, Aux_Datos!$B:$B, VALUE(I16)), "Revisar ID") ) ) -> 46098 | T16: =IF(R16<=0, "PAGADA", IF(P16>0, "PAGO PARCIAL", "PENDIENTE")) -> PAGADA | U16: =IF(AND(T16<>"PAGADA", L16<TODAY()), "CRÍTICO: VENCIDA", IF(T16="PAGADA", "SOLVENTE", "EN TIEMPO")) -> SOLVENTE | V16: =IF(T16="PAGADA", 0, IF(S16 < TODAY(), TODAY() - S16, 0)) -> 0 | W16: =IF(P16=0, "Sin Pago", LET( monedaPago, Q16, descuentoAplicado, G16, limitePermitido, IFERROR(VLOOKUP(monedaPago, 'Limites de Descuento'!$A$2:$B595, 2, FALSE), 0), IF(descuentoAplicado > limitePermitido, "ALERTA: EXCESO (" & TEXT(limitePermitido, "0%") & " máx)", "OK") ) ) -> OK | X16: =IF(OR(H16=0, S16="Sin Pago"), "", IF(AND(H16 > 0, S16 > (L16 + 2)), "⚠️ REVISAR DESCUENTO", "OK")) | Y16: 96 | Z16: CUMPLE
A17: S00024 | B17: 46090.243 | C17: Encamotors Catia C.A | D17: GRIMAN DIAZ HECTOR EDUARDO | E17: 90.44 | F17: 15 días | G17: =IF($E17=0,0,IF(SUMIF(Aux_Datos!$B:$B,$I17,Aux_Datos!$K:$K)/$E17>=VLOOKUP(IF(COUNTIFS(Aux_Datos!$B:$B,$I17,Aux_Datos!$D:$D,"<>USD")=0,"USD","VES"),'Limites de Descuento'!$A$2:$D$4,4,FALSE),MAX(0,1-SUMIF(Aux_Datos!$B:$B,$I17,Aux_Datos!$K:$K)/$E17),0)) -> 0 | I17: =VALUE(MID(A17,2,LEN(A17))) -> 24 | J17: =INT(B17) -> 46090 | K17: =IF(F17="Pago inmediato", 0, IF(F17="", "", IFERROR(VALUE(MID(F17, 1, SEARCH(" ", F17)-1)), ""))) -> 15 | L17: =J17+K17+1 -> 46106 | M17: =E17-(E17*G17)-(E17*H17) -> 90.44 | N17: =IF(T17="PAGADA", 0, IF(L17 < TODAY(), TODAY() - L17, 0)) -> 0 | O17: =IF(T17="PAGADA", "PAGADA", IF(L17 < TODAY(), "VENCIDA", "EN TIEMPO")) -> PAGADA | P17: =LET( idVenta, I17&"", montoTotal, M17, pagos, IFERROR(SUMIF(Aux_Datos!$B:$B, idVenta, Aux_Datos!$K:$K), 0), retenciones, IFERROR(SUMIF(Aux_Datos!$N:$N, idVenta, Aux_Datos!$R:$R), 0), pagos + retenciones ) -> 101.23959 | Q17: =IF(P17=0, "Sin Pago", LET( idVenta, I17&"", montoTotalPagado, P17, pagoUSD, IFERROR(SUMIFS(Aux_Datos!$C:$C, Aux_Datos!$B:$B, idVenta, Aux_Datos!$D:$D, "USD"), 0), pagoVES, IFERROR(SUMIFS(Aux_Datos!$C:$C, Aux_Datos!$B:$B, idVenta, Aux_Datos!$D:$D, "VES"), 0), IF(pagoUSD >= (montoTotalPagado * 0.84), "USD", IF(pagoVES >= (montoTotalPagado * 0.84), "VES", "MIXTO")) ) ) -> VES | R17: =M17-P17 -> -10.799592 | S17: =IF(P17=0, "Sin Pago", IFERROR( MAXIFS(Aux_Datos!$A:$A, Aux_Datos!$B:$B, I17&""), IFERROR(MAXIFS(Aux_Datos!$A:$A, Aux_Datos!$B:$B, VALUE(I17)), "Revisar ID") ) ) -> 46133 | T17: =IF(R17<=0, "PAGADA", IF(P17>0, "PAGO PARCIAL", "PENDIENTE")) -> PAGADA | U17: =IF(AND(T17<>"PAGADA", L17<TODAY()), "CRÍTICO: VENCIDA", IF(T17="PAGADA", "SOLVENTE", "EN TIEMPO")) -> SOLVENTE | V17: =IF(T17="PAGADA", 0, IF(S17 < TODAY(), TODAY() - S17, 0)) -> 0 | W17: =IF(P17=0, "Sin Pago", LET( monedaPago, Q17, descuentoAplicado, G17, limitePermitido, IFERROR(VLOOKUP(monedaPago, 'Limites de Descuento'!$A$2:$B595, 2, FALSE), 0), IF(descuentoAplicado > limitePermitido, "ALERTA: EXCESO (" & TEXT(limitePermitido, "0%") & " máx)", "OK") ) ) -> OK | X17: =IF(OR(H17=0, S17="Sin Pago"), "", IF(AND(H17 > 0, S17 > (L17 + 2)), "⚠️ REVISAR DESCUENTO", "OK")) | Y17: 101.23959 | Z17: CUMPLE
A18: S00026 | B18: 46090.243 | C18: Joel Duque | D18: CASERES GONZALEZ RONALD OSWALDO | E18: 72.48 | F18: 15 días | G18: =IF($E18=0,0,IF(SUMIF(Aux_Datos!$B:$B,$I18,Aux_Datos!$K:$K)/$E18>=VLOOKUP(IF(COUNTIFS(Aux_Datos!$B:$B,$I18,Aux_Datos!$D:$D,"<>USD")=0,"USD","VES"),'Limites de Descuento'!$A$2:$D$4,4,FALSE),MAX(0,1-SUMIF(Aux_Datos!$B:$B,$I18,Aux_Datos!$K:$K)/$E18),0)) -> 0 | I18: =VALUE(MID(A18,2,LEN(A18))) -> 26 | J18: =INT(B18) -> 46090 | K18: =IF(F18="Pago inmediato", 0, IF(F18="", "", IFERROR(VALUE(MID(F18, 1, SEARCH(" ", F18)-1)), ""))) -> 15 | L18: =J18+K18+1 -> 46106 | M18: =E18-(E18*G18)-(E18*H18) -> 72.48 | N18: =IF(T18="PAGADA", 0, IF(L18 < TODAY(), TODAY() - L18, 0)) -> 94 | O18: =IF(T18="PAGADA", "PAGADA", IF(L18 < TODAY(), "VENCIDA", "EN TIEMPO")) -> VENCIDA | P18: =LET( idVenta, I18&"", montoTotal, M18, pagos, IFERROR(SUMIF(Aux_Datos!$B:$B, idVenta, Aux_Datos!$K:$K), 0), retenciones, IFERROR(SUMIF(Aux_Datos!$N:$N, idVenta, Aux_Datos!$R:$R), 0), pagos + retenciones ) -> 30 | Q18: =IF(P18=0, "Sin Pago", LET( idVenta, I18&"", montoTotalPagado, P18, pagoUSD, IFERROR(SUMIFS(Aux_Datos!$C:$C, Aux_Datos!$B:$B, idVenta, Aux_Datos!$D:$D, "USD"), 0), pagoVES, IFERROR(SUMIFS(Aux_Datos!$C:$C, Aux_Datos!$B:$B, idVenta, Aux_Datos!$D:$D, "VES"), 0), IF(pagoUSD >= (montoTotalPagado * 0.84), "USD", IF(pagoVES >= (montoTotalPagado * 0.84), "VES", "MIXTO")) ) ) -> USD | R18: =M18-P18 -> 42.48 | S18: =IF(P18=0, "Sin Pago", IFERROR( MAXIFS(Aux_Datos!$A:$A, Aux_Datos!$B:$B, I18&""), IFERROR(MAXIFS(Aux_Datos!$A:$A, Aux_Datos!$B:$B, VALUE(I18)), "Revisar ID") ) ) -> 46175 | T18: =IF(R18<=0, "PAGADA", IF(P18>0, "PAGO PARCIAL", "PENDIENTE")) -> PAGO PARCIAL | U18: =IF(AND(T18<>"PAGADA", L18<TODAY()), "CRÍTICO: VENCIDA", IF(T18="PAGADA", "SOLVENTE", "EN TIEMPO")) -> CRÍTICO: VENCIDA | V18: =IF(T18="PAGADA", 0, IF(S18 < TODAY(), TODAY() - S18, 0)) -> 25 | W18: =IF(P18=0, "Sin Pago", LET( monedaPago, Q18, descuentoAplicado, G18, limitePermitido, IFERROR(VLOOKUP(monedaPago, 'Limites de Descuento'!$A$2:$B595, 2, FALSE), 0), IF(descuentoAplicado > limitePermitido, "ALERTA: EXCESO (" & TEXT(limitePermitido, "0%") & " máx)", "OK") ) ) -> OK | X18: =IF(OR(H18=0, S18="Sin Pago"), "", IF(AND(H18 > 0, S18 > (L18 + 2)), "⚠️ REVISAR DESCUENTO", "OK")) | Y18: 30 | Z18: NO CUMPLE
A19: S00027 | B19: 46090.244 | C19: Moises Alejandro Mares | D19: GRIMAN DIAZ HECTOR EDUARDO | E19: 510 | F19: 15 días | G19: =IF($E19=0,0,IF(SUMIF(Aux_Datos!$B:$B,$I19,Aux_Datos!$K:$K)/$E19>=VLOOKUP(IF(COUNTIFS(Aux_Datos!$B:$B,$I19,Aux_Datos!$D:$D,"<>USD")=0,"USD","VES"),'Limites de Descuento'!$A$2:$D$4,4,FALSE),MAX(0,1-SUMIF(Aux_Datos!$B:$B,$I19,Aux_Datos!$K:$K)/$E19),0)) -> 0 | I19: =VALUE(MID(A19,2,LEN(A19))) -> 27 | J19: =INT(B19) -> 46090 | K19: =IF(F19="Pago inmediato", 0, IF(F19="", "", IFERROR(VALUE(MID(F19, 1, SEARCH(" ", F19)-1)), ""))) -> 15 | L19: =J19+K19+1 -> 46106 | M19: =E19-(E19*G19)-(E19*H19) -> 510 | N19: =IF(T19="PAGADA", 0, IF(L19 < TODAY(), TODAY() - L19, 0)) -> 94 | O19: =IF(T19="PAGADA", "PAGADA", IF(L19 < TODAY(), "VENCIDA", "EN TIEMPO")) -> VENCIDA | P19: =LET( idVenta, I19&"", montoTotal, M19, pagos, IFERROR(SUMIF(Aux_Datos!$B:$B, idVenta, Aux_Datos!$K:$K), 0), retenciones, IFERROR(SUMIF(Aux_Datos!$N:$N, idVenta, Aux_Datos!$R:$R), 0), pagos + retenciones ) -> 150 | Q19: =IF(P19=0, "Sin Pago", LET( idVenta, I19&"", montoTotalPagado, P19, pagoUSD, IFERROR(SUMIFS(Aux_Datos!$C:$C, Aux_Datos!$B:$B, idVenta, Aux_Datos!$D:$D, "USD"), 0), pagoVES, IFERROR(SUMIFS(Aux_Datos!$C:$C, Aux_Datos!$B:$B, idVenta, Aux_Datos!$D:$D, "VES"), 0), IF(pagoUSD >= (montoTotalPagado * 0.84), "USD", IF(pagoVES >= (montoTotalPagado * 0.84), "VES", "MIXTO")) ) ) -> USD | R19: =M19-P19 -> 360 | S19: =IF(P19=0, "Sin Pago", IFERROR( MAXIFS(Aux_Datos!$A:$A, Aux_Datos!$B:$B, I19&""), IFERROR(MAXIFS(Aux_Datos!$A:$A, Aux_Datos!$B:$B, VALUE(I19)), "Revisar ID") ) ) -> 46192 | T19: =IF(R19<=0, "PAGADA", IF(P19>0, "PAGO PARCIAL", "PENDIENTE")) -> PAGO PARCIAL | U19: =IF(AND(T19<>"PAGADA", L19<TODAY()), "CRÍTICO: VENCIDA", IF(T19="PAGADA", "SOLVENTE", "EN TIEMPO")) -> CRÍTICO: VENCIDA | V19: =IF(T19="PAGADA", 0, IF(S19 < TODAY(), TODAY() - S19, 0)) -> 8 | W19: =IF(P19=0, "Sin Pago", LET( monedaPago, Q19, descuentoAplicado, G19, limitePermitido, IFERROR(VLOOKUP(monedaPago, 'Limites de Descuento'!$A$2:$B595, 2, FALSE), 0), IF(descuentoAplicado > limitePermitido, "ALERTA: EXCESO (" & TEXT(limitePermitido, "0%") & " máx)", "OK") ) ) -> OK | X19: =IF(OR(H19=0, S19="Sin Pago"), "", IF(AND(H19 > 0, S19 > (L19 + 2)), "⚠️ REVISAR DESCUENTO", "OK")) | Y19: 150 | Z19: NO CUMPLE
A20: S00028 | B20: 46085.588 | C20: Ricardo A. Fernandez. | D20: MARTINEZ MONTES JEFFREY ENRIQUE | E20: 69.28 | F20: 15 días | G20: =IF($E20=0,0,IF(SUMIF(Aux_Datos!$B:$B,$I20,Aux_Datos!$K:$K)/$E20>=VLOOKUP(IF(COUNTIFS(Aux_Datos!$B:$B,$I20,Aux_Datos!$D:$D,"<>USD")=0,"USD","VES"),'Limites de Descuento'!$A$2:$D$4,4,FALSE),MAX(0,1-SUMIF(Aux_Datos!$B:$B,$I20,Aux_Datos!$K:$K)/$E20),0)) -> 0.005312316 | I20: =VALUE(MID(A20,2,LEN(A20))) -> 28 | J20: =INT(B20) -> 46085 | K20: =IF(F20="Pago inmediato", 0, IF(F20="", "", IFERROR(VALUE(MID(F20, 1, SEARCH(" ", F20)-1)), ""))) -> 15 | L20: =J20+K20+1 -> 46101 | M20: =E20-(E20*G20)-(E20*H20) -> 68.911963 | N20: =IF(T20="PAGADA", 0, IF(L20 < TODAY(), TODAY() - L20, 0)) -> 0 | O20: =IF(T20="PAGADA", "PAGADA", IF(L20 < TODAY(), "VENCIDA", "EN TIEMPO")) -> PAGADA | P20: =LET( idVenta, I20&"", montoTotal, M20, pagos, IFERROR(SUMIF(Aux_Datos!$B:$B, idVenta, Aux_Datos!$K:$K), 0), retenciones, IFERROR(SUMIF(Aux_Datos!$N:$N, idVenta, Aux_Datos!$R:$R), 0), pagos + retenciones ) -> 68.911963 | Q20: =IF(P20=0, "Sin Pago", LET( idVenta, I20&"", montoTotalPagado, P20, pagoUSD, IFERROR(SUMIFS(Aux_Datos!$C:$C, Aux_Datos!$B:$B, idVenta, Aux_Datos!$D:$D, "USD"), 0), pagoVES, IFERROR(SUMIFS(Aux_Datos!$C:$C, Aux_Datos!$B:$B, idVenta, Aux_Datos!$D:$D, "VES"), 0), IF(pagoUSD >= (montoTotalPagado * 0.84), "USD", IF(pagoVES >= (montoTotalPagado * 0.84), "VES", "MIXTO")) ) ) -> VES | R20: =M20-P20 -> 0 | S20: =IF(P20=0, "Sin Pago", IFERROR( MAXIFS(Aux_Datos!$A:$A, Aux_Datos!$B:$B, I20&""), IFERROR(MAXIFS(Aux_Datos!$A:$A, Aux_Datos!$B:$B, VALUE(I20)), "Revisar ID") ) ) -> 46086 | T20: =IF(R20<=0, "PAGADA", IF(P20>0, "PAGO PARCIAL", "PENDIENTE")) -> PAGADA | U20: =IF(AND(T20<>"PAGADA", L20<TODAY()), "CRÍTICO: VENCIDA", IF(T20="PAGADA", "SOLVENTE", "EN TIEMPO")) -> SOLVENTE | V20: =IF(T20="PAGADA", 0, IF(S20 < TODAY(), TODAY() - S20, 0)) -> 0 | W20: =IF(P20=0, "Sin Pago", LET( monedaPago, Q20, descuentoAplicado, G20, limitePermitido, IFERROR(VLOOKUP(monedaPago, 'Limites de Descuento'!$A$2:$B595, 2, FALSE), 0), IF(descuentoAplicado > limitePermitido, "ALERTA: EXCESO (" & TEXT(limitePermitido, "0%") & " máx)", "OK") ) ) -> OK | X20: =IF(OR(H20=0, S20="Sin Pago"), "", IF(AND(H20 > 0, S20 > (L20 + 2)), "⚠️ REVISAR DESCUENTO", "OK")) | Y20: 68.911963 | Z20: CUMPLE
A21: S00029 | B21: 46090.243 | C21: AUTOREPUESTOS SION C.A. | D21: TORO ARDILES DAVID JOSE | E21: 261.98 | F21: 7 días | G21: =IF($E21=0,0,IF(SUMIF(Aux_Datos!$B:$B,$I21,Aux_Datos!$K:$K)/$E21>=VLOOKUP(IF(COUNTIFS(Aux_Datos!$B:$B,$I21,Aux_Datos!$D:$D,"<>USD")=0,"USD","VES"),'Limites de Descuento'!$A$2:$D$4,4,FALSE),MAX(0,1-SUMIF(Aux_Datos!$B:$B,$I21,Aux_Datos!$K:$K)/$E21),0)) -> 0.24421712 | I21: =VALUE(MID(A21,2,LEN(A21))) -> 29 | J21: =INT(B21) -> 46090 | K21: =IF(F21="Pago inmediato", 0, IF(F21="", "", IFERROR(VALUE(MID(F21, 1, SEARCH(" ", F21)-1)), ""))) -> 7 | L21: =J21+K21+1 -> 46098 | M21: =E21-(E21*G21)-(E21*H21) -> 198 | N21: =IF(T21="PAGADA", 0, IF(L21 < TODAY(), TODAY() - L21, 0)) -> 0 | O21: =IF(T21="PAGADA", "PAGADA", IF(L21 < TODAY(), "VENCIDA", "EN TIEMPO")) -> PAGADA | P21: =LET( idVenta, I21&"", montoTotal, M21, pagos, IFERROR(SUMIF(Aux_Datos!$B:$B, idVenta, Aux_Datos!$K:$K), 0), retenciones, IFERROR(SUMIF(Aux_Datos!$N:$N, idVenta, Aux_Datos!$R:$R), 0), pagos + retenciones ) -> 198 | Q21: =IF(P21=0, "Sin Pago", LET( idVenta, I21&"", montoTotalPagado, P21, pagoUSD, IFERROR(SUMIFS(Aux_Datos!$C:$C, Aux_Datos!$B:$B, idVenta, Aux_Datos!$D:$D, "USD"), 0), pagoVES, IFERROR(SUMIFS(Aux_Datos!$C:$C, Aux_Datos!$B:$B, idVenta, Aux_Datos!$D:$D, "VES"), 0), IF(pagoUSD >= (montoTotalPagado * 0.84), "USD", IF(pagoVES >= (montoTotalPagado * 0.84), "VES", "MIXTO")) ) ) -> USD | R21: =M21-P21 -> 0 | S21: =IF(P21=0, "Sin Pago", IFERROR( MAXIFS(Aux_Datos!$A:$A, Aux_Datos!$B:$B, I21&""), IFERROR(MAXIFS(Aux_Datos!$A:$A, Aux_Datos!$B:$B, VALUE(I21)), "Revisar ID") ) ) -> 46134 | T21: =IF(R21<=0, "PAGADA", IF(P21>0, "PAGO PARCIAL", "PENDIENTE")) -> PAGADA | U21: =IF(AND(T21<>"PAGADA", L21<TODAY()), "CRÍTICO: VENCIDA", IF(T21="PAGADA", "SOLVENTE", "EN TIEMPO")) -> SOLVENTE | V21: =IF(T21="PAGADA", 0, IF(S21 < TODAY(), TODAY() - S21, 0)) -> 0 | W21: =IF(P21=0, "Sin Pago", LET( monedaPago, Q21, descuentoAplicado, G21, limitePermitido, IFERROR(VLOOKUP(monedaPago, 'Limites de Descuento'!$A$2:$B595, 2, FALSE), 0), IF(descuentoAplicado > limitePermitido, "ALERTA: EXCESO (" & TEXT(limitePermitido, "0%") & " máx)", "OK") ) ) -> OK | X21: =IF(OR(H21=0, S21="Sin Pago"), "", IF(AND(H21 > 0, S21 > (L21 + 2)), "⚠️ REVISAR DESCUENTO", "OK")) | Y21: 198 | Z21: CUMPLE
A22: S00030 | B22: 46090.244 | C22: HIDRAULICAS CAICEDO C.A. | D22: VILLABONA CORREA ALBA ESTEFANIA | E22: 146.08 | F22: 7 días | G22: =IF($E22=0,0,IF(SUMIF(Aux_Datos!$B:$B,$I22,Aux_Datos!$K:$K)/$E22>=VLOOKUP(IF(COUNTIFS(Aux_Datos!$B:$B,$I22,Aux_Datos!$D:$D,"<>USD")=0,"USD","VES"),'Limites de Descuento'!$A$2:$D$4,4,FALSE),MAX(0,1-SUMIF(Aux_Datos!$B:$B,$I22,Aux_Datos!$K:$K)/$E22),0)) -> 0.00054764513 | I22: =VALUE(MID(A22,2,LEN(A22))) -> 30 | J22: =INT(B22) -> 46090 | K22: =IF(F22="Pago inmediato", 0, IF(F22="", "", IFERROR(VALUE(MID(F22, 1, SEARCH(" ", F22)-1)), ""))) -> 7 | L22: =J22+K22+1 -> 46098 | M22: =E22-(E22*G22)-(E22*H22) -> 146 | N22: =IF(T22="PAGADA", 0, IF(L22 < TODAY(), TODAY() - L22, 0)) -> 0 | O22: =IF(T22="PAGADA", "PAGADA", IF(L22 < TODAY(), "VENCIDA", "EN TIEMPO")) -> PAGADA | P22: =LET( idVenta, I22&"", montoTotal, M22, pagos, IFERROR(SUMIF(Aux_Datos!$B:$B, idVenta, Aux_Datos!$K:$K), 0), retenciones, IFERROR(SUMIF(Aux_Datos!$N:$N, idVenta, Aux_Datos!$R:$R), 0), pagos + retenciones ) -> 146 | Q22: =IF(P22=0, "Sin Pago", LET( idVenta, I22&"", montoTotalPagado, P22, pagoUSD, IFERROR(SUMIFS(Aux_Datos!$C:$C, Aux_Datos!$B:$B, idVenta, Aux_Datos!$D:$D, "USD"), 0), pagoVES, IFERROR(SUMIFS(Aux_Datos!$C:$C, Aux_Datos!$B:$B, idVenta, Aux_Datos!$D:$D, "VES"), 0), IF(pagoUSD >= (montoTotalPagado * 0.84), "USD", IF(pagoVES >= (montoTotalPagado * 0.84), "VES", "MIXTO")) ) ) -> USD | R22: =M22-P22 -> 0 | S22: =IF(P22=0, "Sin Pago", IFERROR( MAXIFS(Aux_Datos!$A:$A, Aux_Datos!$B:$B, I22&""), IFERROR(MAXIFS(Aux_Datos!$A:$A, Aux_Datos!$B:$B, VALUE(I22)), "Revisar ID") ) ) -> 46098 | T22: =IF(R22<=0, "PAGADA", IF(P22>0, "PAGO PARCIAL", "PENDIENTE")) -> PAGADA | U22: =IF(AND(T22<>"PAGADA", L22<TODAY()), "CRÍTICO: VENCIDA", IF(T22="PAGADA", "SOLVENTE", "EN TIEMPO")) -> SOLVENTE | V22: =IF(T22="PAGADA", 0, IF(S22 < TODAY(), TODAY() - S22, 0)) -> 0 | W22: =IF(P22=0, "Sin Pago", LET( monedaPago, Q22, descuentoAplicado, G22, limitePermitido, IFERROR(VLOOKUP(monedaPago, 'Limites de Descuento'!$A$2:$B595, 2, FALSE), 0), IF(descuentoAplicado > limitePermitido, "ALERTA: EXCESO (" & TEXT(limitePermitido, "0%") & " máx)", "OK") ) ) -> OK | X22: =IF(OR(H22=0, S22="Sin Pago"), "", IF(AND(H22 > 0, S22 > (L22 + 2)), "⚠️ REVISAR DESCUENTO", "OK")) | Y22: 146 | Z22: CUMPLE
A23: S00031 | B23: 46090.243 | C23: COMERCIAL REPUESTOS MUNDIALES RMS 2022 C.A. | D23: TORO ARDILES DAVID JOSE | E23: 289.16 | F23: 7 días | G23: =IF($E23=0,0,IF(SUMIF(Aux_Datos!$B:$B,$I23,Aux_Datos!$K:$K)/$E23>=VLOOKUP(IF(COUNTIFS(Aux_Datos!$B:$B,$I23,Aux_Datos!$D:$D,"<>USD")=0,"USD","VES"),'Limites de Descuento'!$A$2:$D$4,4,FALSE),MAX(0,1-SUMIF(Aux_Datos!$B:$B,$I23,Aux_Datos!$K:$K)/$E23),0)) -> 0 | I23: =VALUE(MID(A23,2,LEN(A23))) -> 31 | J23: =INT(B23) -> 46090 | K23: =IF(F23="Pago inmediato", 0, IF(F23="", "", IFERROR(VALUE(MID(F23, 1, SEARCH(" ", F23)-1)), ""))) -> 7 | L23: =J23+K23+1 -> 46098 | M23: =E23-(E23*G23)-(E23*H23) -> 289.16 | N23: =IF(T23="PAGADA", 0, IF(L23 < TODAY(), TODAY() - L23, 0)) -> 102 | O23: =IF(T23="PAGADA", "PAGADA", IF(L23 < TODAY(), "VENCIDA", "EN TIEMPO")) -> VENCIDA | P23: =LET( idVenta, I23&"", montoTotal, M23, pagos, IFERROR(SUMIF(Aux_Datos!$B:$B, idVenta, Aux_Datos!$K:$K), 0), retenciones, IFERROR(SUMIF(Aux_Datos!$N:$N, idVenta, Aux_Datos!$R:$R), 0), pagos + retenciones ) -> 50 | Q23: =IF(P23=0, "Sin Pago", LET( idVenta, I23&"", montoTotalPagado, P23, pagoUSD, IFERROR(SUMIFS(Aux_Datos!$C:$C, Aux_Datos!$B:$B, idVenta, Aux_Datos!$D:$D, "USD"), 0), pagoVES, IFERROR(SUMIFS(Aux_Datos!$C:$C, Aux_Datos!$B:$B, idVenta, Aux_Datos!$D:$D, "VES"), 0), IF(pagoUSD >= (montoTotalPagado * 0.84), "USD", IF(pagoVES >= (montoTotalPagado * 0.84), "VES", "MIXTO")) ) ) -> VES | R23: =M23-P23 -> 239.16 | S23: =IF(P23=0, "Sin Pago", IFERROR( MAXIFS(Aux_Datos!$A:$A, Aux_Datos!$B:$B, I23&""), IFERROR(MAXIFS(Aux_Datos!$A:$A, Aux_Datos!$B:$B, VALUE(I23)), "Revisar ID") ) ) -> 46183 | T23: =IF(R23<=0, "PAGADA", IF(P23>0, "PAGO PARCIAL", "PENDIENTE")) -> PAGO PARCIAL | U23: =IF(AND(T23<>"PAGADA", L23<TODAY()), "CRÍTICO: VENCIDA", IF(T23="PAGADA", "SOLVENTE", "EN TIEMPO")) -> CRÍTICO: VENCIDA | V23: =IF(T23="PAGADA", 0, IF(S23 < TODAY(), TODAY() - S23, 0)) -> 17 | W23: =IF(P23=0, "Sin Pago", LET( monedaPago, Q23, descuentoAplicado, G23, limitePermitido, IFERROR(VLOOKUP(monedaPago, 'Limites de Descuento'!$A$2:$B595, 2, FALSE), 0), IF(descuentoAplicado > limitePermitido, "ALERTA: EXCESO (" & TEXT(limitePermitido, "0%") & " máx)", "OK") ) ) -> OK | X23: =IF(OR(H23=0, S23="Sin Pago"), "", IF(AND(H23 > 0, S23 > (L23 + 2)), "⚠️ REVISAR DESCUENTO", "OK")) | Y23: 50 | Z23: NO CUMPLE
A24: S00032 | B24: 46090.243 | C24: Ferretería JJ Martins c.a | D24: TORO ARDILES DAVID JOSE | E24: 101 | F24: 7 días | G24: =IF($E24=0,0,IF(SUMIF(Aux_Datos!$B:$B,$I24,Aux_Datos!$K:$K)/$E24>=VLOOKUP(IF(COUNTIFS(Aux_Datos!$B:$B,$I24,Aux_Datos!$D:$D,"<>USD")=0,"USD","VES"),'Limites de Descuento'!$A$2:$D$4,4,FALSE),MAX(0,1-SUMIF(Aux_Datos!$B:$B,$I24,Aux_Datos!$K:$K)/$E24),0)) -> 0.14156227 | I24: =VALUE(MID(A24,2,LEN(A24))) -> 32 | J24: =INT(B24) -> 46090 | K24: =IF(F24="Pago inmediato", 0, IF(F24="", "", IFERROR(VALUE(MID(F24, 1, SEARCH(" ", F24)-1)), ""))) -> 7 | L24: =J24+K24+1 -> 46098 | M24: =E24-(E24*G24)-(E24*H24) -> 86.70221 | N24: =IF(T24="PAGADA", 0, IF(L24 < TODAY(), TODAY() - L24, 0)) -> 0 | O24: =IF(T24="PAGADA", "PAGADA", IF(L24 < TODAY(), "VENCIDA", "EN TIEMPO")) -> PAGADA | P24: =LET( idVenta, I24&"", montoTotal, M24, pagos, IFERROR(SUMIF(Aux_Datos!$B:$B, idVenta, Aux_Datos!$K:$K), 0), retenciones, IFERROR(SUMIF(Aux_Datos!$N:$N, idVenta, Aux_Datos!$R:$R), 0), pagos + retenciones ) -> 86.70221 | Q24: =IF(P24=0, "Sin Pago", LET( idVenta, I24&"", montoTotalPagado, P24, pagoUSD, IFERROR(SUMIFS(Aux_Datos!$C:$C, Aux_Datos!$B:$B, idVenta, Aux_Datos!$D:$D, "USD"), 0), pagoVES, IFERROR(SUMIFS(Aux_Datos!$C:$C, Aux_Datos!$B:$B, idVenta, Aux_Datos!$D:$D, "VES"), 0), IF(pagoUSD >= (montoTotalPagado * 0.84), "USD", IF(pagoVES >= (montoTotalPagado * 0.84), "VES", "MIXTO")) ) ) -> VES | R24: =M24-P24 -> 0 | S24: =IF(P24=0, "Sin Pago", IFERROR( MAXIFS(Aux_Datos!$A:$A, Aux_Datos!$B:$B, I24&""), IFERROR(MAXIFS(Aux_Datos!$A:$A, Aux_Datos!$B:$B, VALUE(I24)), "Revisar ID") ) ) -> 46086 | T24: =IF(R24<=0, "PAGADA", IF(P24>0, "PAGO PARCIAL", "PENDIENTE")) -> PAGADA | U24: =IF(AND(T24<>"PAGADA", L24<TODAY()), "CRÍTICO: VENCIDA", IF(T24="PAGADA", "SOLVENTE", "EN TIEMPO")) -> SOLVENTE | V24: =IF(T24="PAGADA", 0, IF(S24 < TODAY(), TODAY() - S24, 0)) -> 0 | W24: =IF(P24=0, "Sin Pago", LET( monedaPago, Q24, descuentoAplicado, G24, limitePermitido, IFERROR(VLOOKUP(monedaPago, 'Limites de Descuento'!$A$2:$B595, 2, FALSE), 0), IF(descuentoAplicado > limitePermitido, "ALERTA: EXCESO (" & TEXT(limitePermitido, "0%") & " máx)", "OK") ) ) -> OK | X24: =IF(OR(H24=0, S24="Sin Pago"), "", IF(AND(H24 > 0, S24 > (L24 + 2)), "⚠️ REVISAR DESCUENTO", "OK")) | Y24: 86.70221 | Z24: CUMPLE
A25: S00033 | B25: 46086.364 | C25: Angel ARMAS | D25: REVERON DE CONTRERAS MELANI AUSMAR | E25: 243.01 | F25: Pago inmediato | G25: =IF($E25=0,0,IF(SUMIF(Aux_Datos!$B:$B,$I25,Aux_Datos!$K:$K)/$E25>=VLOOKUP(IF(COUNTIFS(Aux_Datos!$B:$B,$I25,Aux_Datos!$D:$D,"<>USD")=0,"USD","VES"),'Limites de Descuento'!$A$2:$D$4,4,FALSE),MAX(0,1-SUMIF(Aux_Datos!$B:$B,$I25,Aux_Datos!$K:$K)/$E25),0)) -> 0.19756389 | I25: =VALUE(MID(A25,2,LEN(A25))) -> 33 | J25: =INT(B25) -> 46086 | K25: =IF(F25="Pago inmediato", 0, IF(F25="", "", IFERROR(VALUE(MID(F25, 1, SEARCH(" ", F25)-1)), ""))) -> 0 | L25: =J25+K25+1 -> 46087 | M25: =E25-(E25*G25)-(E25*H25) -> 195 | N25: =IF(T25="PAGADA", 0, IF(L25 < TODAY(), TODAY() - L25, 0)) -> 0 | O25: =IF(T25="PAGADA", "PAGADA", IF(L25 < TODAY(), "VENCIDA", "EN TIEMPO")) -> PAGADA | P25: =LET( idVenta, I25&"", montoTotal, M25, pagos, IFERROR(SUMIF(Aux_Datos!$B:$B, idVenta, Aux_Datos!$K:$K), 0), retenciones, IFERROR(SUMIF(Aux_Datos!$N:$N, idVenta, Aux_Datos!$R:$R), 0), pagos + retenciones ) -> 195 | Q25: =IF(P25=0, "Sin Pago", LET( idVenta, I25&"", montoTotalPagado, P25, pagoUSD, IFERROR(SUMIFS(Aux_Datos!$C:$C, Aux_Datos!$B:$B, idVenta, Aux_Datos!$D:$D, "USD"), 0), pagoVES, IFERROR(SUMIFS(Aux_Datos!$C:$C, Aux_Datos!$B:$B, idVenta, Aux_Datos!$D:$D, "VES"), 0), IF(pagoUSD >= (montoTotalPagado * 0.84), "USD", IF(pagoVES >= (montoTotalPagado * 0.84), "VES", "MIXTO")) ) ) -> USD | R25: =M25-P25 -> 0 | S25: =IF(P25=0, "Sin Pago", IFERROR( MAXIFS(Aux_Datos!$A:$A, Aux_Datos!$B:$B, I25&""), IFERROR(MAXIFS(Aux_Datos!$A:$A, Aux_Datos!$B:$B, VALUE(I25)), "Revisar ID") ) ) -> 46086 | T25: =IF(R25<=0, "PAGADA", IF(P25>0, "PAGO PARCIAL", "PENDIENTE")) -> PAGADA | U25: =IF(AND(T25<>"PAGADA", L25<TODAY()), "CRÍTICO: VENCIDA", IF(T25="PAGADA", "SOLVENTE", "EN TIEMPO")) -> SOLVENTE | V25: =IF(T25="PAGADA", 0, IF(S25 < TODAY(), TODAY() - S25, 0)) -> 0 | W25: =IF(P25=0, "Sin Pago", LET( monedaPago, Q25, descuentoAplicado, G25, limitePermitido, IFERROR(VLOOKUP(monedaPago, 'Limites de Descuento'!$A$2:$B595, 2, FALSE), 0), IF(descuentoAplicado > limitePermitido, "ALERTA: EXCESO (" & TEXT(limitePermitido, "0%") & " máx)", "OK") ) ) -> OK | X25: =IF(OR(H25=0, S25="Sin Pago"), "", IF(AND(H25 > 0, S25 > (L25 + 2)), "⚠️ REVISAR DESCUENTO", "OK")) | Y25: 195 | Z25: CUMPLE
A26: S00034 | B26: 46090.244 | C26: Miguel Antonio Chacon | D26: GRIMAN DIAZ HECTOR EDUARDO | E26: 185.04 | F26: 15 días | G26: =IF($E26=0,0,IF(SUMIF(Aux_Datos!$B:$B,$I26,Aux_Datos!$K:$K)/$E26>=VLOOKUP(IF(COUNTIFS(Aux_Datos!$B:$B,$I26,Aux_Datos!$D:$D,"<>USD")=0,"USD","VES"),'Limites de Descuento'!$A$2:$D$4,4,FALSE),MAX(0,1-SUMIF(Aux_Datos!$B:$B,$I26,Aux_Datos!$K:$K)/$E26),0)) -> 0 | I26: =VALUE(MID(A26,2,LEN(A26))) -> 34 | J26: =INT(B26) -> 46090 | K26: =IF(F26="Pago inmediato", 0, IF(F26="", "", IFERROR(VALUE(MID(F26, 1, SEARCH(" ", F26)-1)), ""))) -> 15 | L26: =J26+K26+1 -> 46106 | M26: =E26-(E26*G26)-(E26*H26) -> 185.04 | N26: =IF(T26="PAGADA", 0, IF(L26 < TODAY(), TODAY() - L26, 0)) -> 0 | O26: =IF(T26="PAGADA", "PAGADA", IF(L26 < TODAY(), "VENCIDA", "EN TIEMPO")) -> PAGADA | P26: =LET( idVenta, I26&"", montoTotal, M26, pagos, IFERROR(SUMIF(Aux_Datos!$B:$B, idVenta, Aux_Datos!$K:$K), 0), retenciones, IFERROR(SUMIF(Aux_Datos!$N:$N, idVenta, Aux_Datos!$R:$R), 0), pagos + retenciones ) -> 204.98768 | Q26: =IF(P26=0, "Sin Pago", LET( idVenta, I26&"", montoTotalPagado, P26, pagoUSD, IFERROR(SUMIFS(Aux_Datos!$C:$C, Aux_Datos!$B:$B, idVenta, Aux_Datos!$D:$D, "USD"), 0), pagoVES, IFERROR(SUMIFS(Aux_Datos!$C:$C, Aux_Datos!$B:$B, idVenta, Aux_Datos!$D:$D, "VES"), 0), IF(pagoUSD >= (montoTotalPagado * 0.84), "USD", IF(pagoVES >= (montoTotalPagado * 0.84), "VES", "MIXTO")) ) ) -> VES | R26: =M26-P26 -> -19.947685 | S26: =IF(P26=0, "Sin Pago", IFERROR( MAXIFS(Aux_Datos!$A:$A, Aux_Datos!$B:$B, I26&""), IFERROR(MAXIFS(Aux_Datos!$A:$A, Aux_Datos!$B:$B, VALUE(I26)), "Revisar ID") ) ) -> 46140 | T26: =IF(R26<=0, "PAGADA", IF(P26>0, "PAGO PARCIAL", "PENDIENTE")) -> PAGADA | U26: =IF(AND(T26<>"PAGADA", L26<TODAY()), "CRÍTICO: VENCIDA", IF(T26="PAGADA", "SOLVENTE", "EN TIEMPO")) -> SOLVENTE | V26: =IF(T26="PAGADA", 0, IF(S26 < TODAY(), TODAY() - S26, 0)) -> 0 | W26: =IF(P26=0, "Sin Pago", LET( monedaPago, Q26, descuentoAplicado, G26, limitePermitido, IFERROR(VLOOKUP(monedaPago, 'Limites de Descuento'!$A$2:$B595, 2, FALSE), 0), IF(descuentoAplicado > limitePermitido, "ALERTA: EXCESO (" & TEXT(limitePermitido, "0%") & " máx)", "OK") ) ) -> OK | X26: =IF(OR(H26=0, S26="Sin Pago"), "", IF(AND(H26 > 0, S26 > (L26 + 2)), "⚠️ REVISAR DESCUENTO", "OK")) | Y26: 204.98768 | Z26: CUMPLE
